Workbook
Name Costco_Reported_Week: '5_Ref Data EDIT FIRST'!$K$10
Name Costco_Weeks_in_previous_month: '5_Ref Data EDIT FIRST'!$K$11
Name FD_Latest_Week: '5_Ref Data EDIT FIRST'!$I$12
Name FD_Reported_Week: #REF!
Name FD_Reported_Week: '5_Ref Data EDIT FIRST'!$I$10
Name FD_Weeks_in_previous_month: #REF!
Name FD_Weeks_in_previous_month: '5_Ref Data EDIT FIRST'!$I$11
Name new: #REF!
Name WM_Reprted_Week: '5_Ref Data EDIT FIRST'!$J$10
Name WM_Weeks_in_previous_month: '5_Ref Data EDIT FIRST'!$J$11

Sheet Instructions
B2: Assignment 4a - "A_match segment using max index" sheet instructions:
B4: Use functions to identify the segment membership using indices:(Each member belongs to the segment having the highest index)
B6: For Ex. | C6: Membership_Number | D6: FH | E6: DF | F6: TH | G6: C | H6: E | I6: BH | J6: Segment
C7: 3269653 | D7: 0.044702023 | E7: 0.42902254 | F7: 0.23170049 | G7: 0.59133723 | H7: 0.67895861 | I7: 0.28982332
B9: Output: | C9: Membership_Number | D9: FH | E9: DF | F9: TH | G9: C | H9: E | I9: BH | J9: Segment
C10: 3269653 | D10: 0.044702023 | E10: 0.42902254 | F10: 0.23170049 | G10: 0.59133723 | H10: 0.67895861 | I10: 0.28982332 | J10: E
B12: Go to Assignment 4a
B16: Assignment 4b - "B_hlookup and sumif" sheet instructions:
B17: 1) | C17: Lookup the data for each of the variables (E5:R5) from "DATA FOR ASSIGNMENT 4b" sheet and fill up cells
B18: from E6:R108 in ‘HLookup_Sumif’ sheet. This values is called as ‘Volume’.
B19: 2) | C19: Multiply Volume by Coefficients (E4:R4) and update cells E6:R108 in place.
B20: 3) | C20: For Base Volume calculation (column’S’) , Sum up values from cell E:R if these values are negative.
B21: Also, add a Constant (D4) in this calculation. (E.g: S6 is sum of E6:R6)
B22: Go to Assignment 4b
B26: Assignment 4c - "C_string functions" sheet instructions:
B28: Use a single string function in each column to separate parts of the string variable names (do not use 'TEXT TO COLUMNS' feature):
B30: For Ex. | C30: Variable | F30: measure | G30: category | H30: brand | I30: size
C31: onhand.CONDITIONER.Aussie.BASE | F31: onhand | G31: CONDITIONER | H31: Aussie | I31: Base
B33: Go to Assignment 4c
B37: Assignment 4d - "D_ranking within group" sheet instructions:
B39: Use of SUMPRODUCT to rank within groups:
B40: There are several groups in sample data. Instead of ranking overall, you have to rank within groups. Use sumproduct function.
B41: Also you have to find unique rank within group only.
B43: For Ex. | C43: Group | D43: Value | E43: Rank | F43: Unique Rank
C44: A | D44: 10 | E44: 1 | F44: 1
C45: A | D45: 26 | E45: 2 | F45: 2
C46: A | D46: 34 | E46: 3 | F46: 3
C47: A | D47: 34 | E47: 3 | F47: 4
C48: B | D48: 34 | E48: 1 | F48: 1
C49: B | D49: 34 | E49: 1 | F49: 2
C50: B | D50: 61 | E50: 3 | F50: 3
C51: B | D51: 72 | E51: 4 | F51: 4
B53: Go to Assignment 4d
B57: Assignment 4e - "E_mix of if & concat in matrix" sheet instructions:
B59: Use a single formula to compute Price Indices for the psu's in each row with respect to psu's in columns. Do not compute price indices with respect to self.
B61: For ex. | E61: model prices
C62: All prices | D62: brand | E62: 1 | F62: 2 | G62: 6
C63: brand | D63: variables | E63: psu.1 | F63: psu.2 | G63: psu.6
C64: 1 | D64: psu.1 | F64: =2/1 | G64: =6/1
B66: Go to Assignment 4e
...

Sheet A_match segment using max index
A1: Back to Instructions
B3: Membership_Number | C3: FH | D3: DF | E3: TH | F3: C | G3: E | H3: BH | I3: Segment
B4: 3269653 | C4: 0.044702023 | D4: 0.42902254 | E4: 0.23170049 | F4: 0.59133723 | G4: 0.67895861 | H4: 0.28982332 | I4: =INDEX($C$3:$H$3, MATCH(MAX(C4:H4), C4:H4, 0)) -> E
B5: 10765258 | C5: 0.22774726 | D5: 0.6094659 | E5: 0.90799471 | F5: 0.69408566 | G5: 0.83284129 | H5: 0.29431808 | I5: =INDEX($C$3:$H$3, MATCH(MAX(C5:H5), C5:H5, 0)) -> TH
B6: 45899740 | C6: 0.54394797 | D6: 0.80754356 | E6: 0.20519363 | F6: 0.31979516 | G6: 0.52154685 | H6: 0.94902079 | I6: =INDEX($C$3:$H$3, MATCH(MAX(C6:H6), C6:H6, 0)) -> BH
B7: 58516647 | C7: 0.062198834 | D7: 0.74555923 | E7: 0.091299717 | F7: 0.57159011 | G7: 0.83823492 | H7: 0.23721814 | I7: =INDEX($C$3:$H$3, MATCH(MAX(C7:H7), C7:H7, 0)) -> E
B8: 100072869 | C8: 0.36745192 | D8: 0.74178084 | E8: 0.65082003 | F8: 0.9146544 | G8: 0.8170256 | H8: 0.33412966 | I8: =INDEX($C$3:$H$3, MATCH(MAX(C8:H8), C8:H8, 0)) -> C
B9: 100081885 | C9: 0.37461152 | D9: 0.29349147 | E9: 0.91991055 | F9: 0.40548746 | G9: 0.67388967 | H9: 0.025161932 | I9: =INDEX($C$3:$H$3, MATCH(MAX(C9:H9), C9:H9, 0)) -> TH
B10: 100083099 | C10: 0.084652437 | D10: 0.68429859 | E10: 0.81472795 | F10: 0.0050986866 | G10: 0.13704246 | H10: 0.65449875 | I10: =INDEX($C$3:$H$3, MATCH(MAX(C10:H10), C10:H10, 0)) -> TH
B11: 100088444 | C11: 0.14609908 | D11: 0.92248187 | E11: 0.1939272 | F11: 0.23984374 | G11: 0.088616183 | H11: 0.17122855 | I11: =INDEX($C$3:$H$3, MATCH(MAX(C11:H11), C11:H11, 0)) -> DF
B12: 100114564 | C12: 0.88680347 | D12: 0.647865 | E12: 0.49255878 | F12: 0.66043089 | G12: 0.640949 | H12: 0.1812176 | I12: =INDEX($C$3:$H$3, MATCH(MAX(C12:H12), C12:H12, 0)) -> FH
B13: 100115934 | C13: 0.85388184 | D13: 0.017062241 | E13: 0.10188535 | F13: 0.97889499 | G13: 0.096045431 | H13: 0.014550725 | I13: =INDEX($C$3:$H$3, MATCH(MAX(C13:H13), C13:H13, 0)) -> C
B14: 100125462 | C14: 0.79648918 | D14: 0.35468884 | E14: 0.80720321 | F14: 0.52943037 | G14: 0.01525119 | H14: 0.0033212132 | I14: =INDEX($C$3:$H$3, MATCH(MAX(C14:H14), C14:H14, 0)) -> TH
B15: 100159772 | C15: 0.65050997 | D15: 0.63469504 | E15: 0.22374359 | F15: 0.62156294 | G15: 0.9481728 | H15: 0.36639744 | I15: =INDEX($C$3:$H$3, MATCH(MAX(C15:H15), C15:H15, 0)) -> E
... B19853: 990099081 | C19853: 0.37993114 | D19853: 0.71467277 | E19853: 0.75778721 | F19853: 0.88993542 | G19853: 0.89335873 | H19853: 0.657037 | I19853: =INDEX($C$3:$H$3, MATCH(MAX(C19853:H19853), C19853:H19853, 0)) -> E

Sheet DATA FOR ASSIGNMENT 4b
E1: Back to Instructions
A2: week | B2: msu.75711.ACE.POLVO.BEBE | C2: msu.112089.ARIEL.POLVO.TANGO | D2: msu.147030.ACE.POLVO.MB | E2: msu.149681.ML.POLVO.MB | F2: msu.170196.ARIEL.LIQUIDO.MB | G2: msu.179122.ACE.POLVO.AFL | H2: msu.179122.ACE.POLVO.LIMON | I2: msu.183906.ARIEL.LIQUIDO.MB | J2: msu.188231.ARIEL.POLVO.MB | K2: msu.188238.BOLD.POLVO.MB | L2: msu.188245.ACE.POLVO.MB | M2: msu.188252.ARIEL.POLVO.BESPUMA | N2: msu.188259.ARIEL.POLVO.CDOWNY | O2: msu.208634.ACE.POLVO.MB | P2: msu.231508.ARIEL.POLVO.BLACK | Q2: msu.233540.BOLD.POLVO.MB | R2: msu.255653.ARIEL.LIQUIDO.BLACK | S2: msu.267672.ACE.POLVO.ROSAS | T2: msu.277122.ACE.POLVO.AFL | U2: msu.278095.ACE.LIQUIDO.MB | V2: sales.75711.ACE.POLVO.BEBE | W2: sales.112089.ARIEL.POLVO.TANGO | X2: sales.147030.ACE.POLVO.MB | Y2: sales.149681.ML.POLVO.MB | Z2: sales.170196.ARIEL.LIQUIDO.MB | AA2: sales.179122.ACE.POLVO.AFL | AB2: sales.179122.ACE.POLVO.LIMON | AC2: sales.183906.ARIEL.LIQUIDO.MB | AD2: sales.188231.ARIEL.POLVO.MB | AE2: sales.188238.BOLD.POLVO.MB | AF2: sales.188245.ACE.POLVO.MB | AG2: sales.188252.ARIEL.POLVO.BESPUMA | AH2: sales.188259.ARIEL.POLVO.CDOWNY | AI2: sales.208634.ACE.POLVO.MB | AJ2: sales.231508.ARIEL.POLVO.BLACK | AK2: sales.233540.BOLD.POLVO.MB | AL2: sales.255653.ARIEL.LIQUIDO.BLACK | AM2: sales.267672.ACE.POLVO.ROSAS | AN2: sales.277122.ACE.POLVO.AFL | AO2: sales.278095.ACE.LIQUIDO.MB | AP2: flyer.Ace.Lqd | AQ2: flyer.Ace.Pwd | AR2: flyer.Ariel.Lqd | AS2: flyer.Ariel.Pwd | AT2: flyer.Bold.Pwd | AU2: flyer.ML.Pwd | AV2: promo.Ace.Lqd.Regular.Na | AW2: promo.Ace.Pwd.Incase.1ltAceLiq | AX2: promo.Ace.Pwd.Incase.1ltArielLiq | AY2: promo.Ace.Pwd.Incase.850mlDowny | AZ2: promo.Ace.Pwd.InOut.Na | BA2: promo.Ace.Pwd.Regular.Na | BB2: promo.Ariel.Lqd.InOut.Na | BC2: promo.Ariel.Lqd.Regular.Na | BD2: promo.Ariel.Pwd.Incase.1ltArielLiq | BE2: promo.Ariel.Pwd.Incase.850mlDowny | BF2: promo.Ariel.Pwd.InOut.850mlDowny | BG2: promo.Ariel.Pwd.InOut.Na | BH2: promo.Ariel.Pwd.Mix.Na | BI2: promo.Ariel.Pwd.Regular.Na | BJ2: promo.Bold.Pwd.Incase.1kg | BK2: promo.Bold.Pwd.Incase.Manta | BL2: promo.Bold.Pwd.Regular.Na | BM2: promo.ML.Pwd.Regular.Na | BN2: pinc.75711.ACE.POLVO.BEBE | BO2: pinc.112089.ARIEL.POLVO.TANGO | BP2: pinc.147030.ACE.POLVO.MB | BQ2: pinc.149681.ML.POLVO.MB | BR2: pinc.170196.ARIEL.LIQUIDO.MB | BS2: pinc.179122.ACE.POLVO.AFL | BT2: pinc.179122.ACE.POLVO.LIMON | BU2: pinc.183906.ARIEL.LIQUIDO.MB | BV2: pinc.188231.ARIEL.POLVO.MB | BW2: pinc.188238.BOLD.POLVO.MB | BX2: pinc.188245.ACE.POLVO.MB | BY2: pinc.188252.ARIEL.POLVO.BESPUMA | BZ2: pinc.188259.ARIEL.POLVO.CDOWNY | CA2: pinc.208634.ACE.POLVO.MB | CB2: pinc.231508.ARIEL.POLVO.BLACK | CC2: pinc.233540.BOLD.POLVO.MB | CD2: pinc.255653.ARIEL.LIQUIDO.BLACK | CE2: pinc.267672.ACE.POLVO.ROSAS | CF2: pinc.277122.ACE.POLVO.AFL | CG2: pinc.278095.ACE.LIQUIDO.MB | CH2: percdisc.278095.ACE.LIQUIDO.MB | CI2: percdisc.179122.ACE.POLVO.AFL | CJ2: percdisc.277122.ACE.POLVO.AFL | CK2: percdisc.75711.ACE.POLVO.BEBE | CL2: percdisc.179122.ACE.POLVO.LIMON | CM2: percdisc.147030.ACE.POLVO.MB | CN2: percdisc.188245.ACE.POLVO.MB | CO2: percdisc.208634.ACE.POLVO.MB | CP2: percdisc.267672.ACE.POLVO.ROSAS | CQ2: percdisc.255653.ARIEL.LIQUIDO.BLACK | CR2: percdisc.170196.ARIEL.LIQUIDO.MB | CS2: percdisc.183906.ARIEL.LIQUIDO.MB | CT2: percdisc.188252.ARIEL.POLVO.BESPUMA | CU2: percdisc.231508.ARIEL.POLVO.BLACK | CV2: percdisc.231508.ARIEL.POLVO.BLACK_lt15 | CW2: percdisc.231508.ARIEL.POLVO.BLACK_gt15 | CX2: percdisc.188259.ARIEL.POLVO.CDOWNY | CY2: percdisc.188231.ARIEL.POLVO.MB | CZ2: percdisc.188231.ARIEL.POLVO.MB_10to12 | DA2: percdisc.188231.ARIEL.POLVO.MB_12to14 | DB2: percdisc.188231.ARIEL.POLVO.MB_gt10 | DC2: percdisc.112089.ARIEL.POLVO.TANGO | DD2: percdisc.188238.BOLD.POLVO.MB | DE2: percdisc.233540.BOLD.POLVO.MB | DF2: percdisc.149681.ML.POLVO.MB | DG2: sales.ACE.LIQUIDO | DH2: sales.ACE.POLVO | DI2: sales.ARIEL.LIQUIDO | DJ2: sales.ARIEL.POLVO | DK2: sales.BOLD.POLVO | DL2: sales.ML.POLVO | DM2: msu.ACE.LIQUIDO | DN2: msu.ACE.POLVO | DO2: msu.ARIEL.LIQUIDO | DP2: msu.ARIEL.POLVO | DQ2: msu.BOLD.POLVO | DR2: msu.ML.POLVO | DS2: msu.Ace.Pwd | DT2: msu.Ariel.Pwd | DU2: msu.Bold.Pwd | DV2: msu.ML.Pwd | DW2: msu.Ace.Liq | DX2: msu.Ariel.Liq | DY2: value_BA_Ace_Liq | DZ2: value_BA_Ace_Pwd | EA2: value_BA_Ariel_Liq | EB2: value_BA_Ariel_Pwd | EC2: value_BA_Bold_Pwd | ED2: value_BA_ML_Pwd | EE2: value_SC_Ace_Liq | EF2: value_SC_Ace_Pwd | EG2: value_SC_Ariel_Liq | EH2: value_SC_Ariel_Pwd | EI2: value_SC_Bold_Pwd | EJ2: value_SC_ML_Pwd | EK2: value_SS_Ace_Pwd | EL2: pmsu.ACE.LIQUIDO | EM2: pmsu.ACE.POLVO | EN2: pmsu.ARIEL.LIQUIDO | EO2: pmsu.ARIEL.POLVO | EP2: pmsu.BOLD.POLVO | EQ2: pmsu.ML.POLVO | ER2: pi.ARIEL.LIQUIDO_ACE.LIQUIDO | ES2: pi.ARIEL.POLVO_ACE.POLVO | ET2: pi.BOLD.POLVO_ACE.POLVO | EU2: pi.ML.POLVO_ACE.POLVO | EV2: pi.ACE.LIQUIDO_ARIEL.LIQUIDO | EW2: pi.ACE.POLVO_ARIEL.POLVO | EX2: pi.BOLD.POLVO_ARIEL.POLVO | EY2: pi.ML.POLVO_ARIEL.POLVO | EZ2: pi.ACE.POLVO_BOLD.POLVO | FA2: pi.ARIEL.POLVO_BOLD.POLVO | FB2: pi.ML.POLVO_BOLD.POLVO | FC2: pi.ACE.POLVO_ML.POLVO | FD2: pi.ARIEL.POLVO_ML.POLVO | FE2: pi.BOLD.POLVO_ML.POLVO | FF2: percpinc.75711.ACE.POLVO.BEBE | FG2: percpinc.112089.ARIEL.POLVO.TANGO | FH2: percpinc.147030.ACE.POLVO.MB | FI2: percpinc.149681.ML.POLVO.MB | FJ2: percpinc.170196.ARIEL.LIQUIDO.MB | FK2: percpinc.179122.ACE.POLVO.AFL | FL2: percpinc.179122.ACE.POLVO.LIMON | FM2: percpinc.183906.ARIEL.LIQUIDO.MB | FN2: percpinc.188231.ARIEL.POLVO.MB | FO2: percpinc.188238.BOLD.POLVO.MB | FP2: percpinc.188245.ACE.POLVO.MB | FQ2: percpinc.188252.ARIEL.POLVO.BESPUMA | FR2: percpinc.188259.ARIEL.POLVO.CDOWNY | FS2: percpinc.208634.ACE.POLVO.MB | FT2: percpinc.231508.ARIEL.POLVO.BLACK | FU2: percpinc.233540.BOLD.POLVO.MB | FV2: percpinc.255653.ARIEL.LIQUIDO.BLACK | FW2: percpinc.267672.ACE.POLVO.ROSAS | FX2: percpinc.277122.ACE.POLVO.AFL | FY2: percpinc.278095.ACE.LIQUIDO.MB | FZ2: percdisc.ACE.LIQUIDO | GA2: percdisc.ACE.POLVO | GB2: percdisc.ARIEL.LIQUIDO | GC2: percdisc.ARIEL.POLVO | GD2: percdisc.BOLD.POLVO | GE2: percdisc.ML.POLVO | GF2: percpinc.ACE.LIQUIDO | GG2: percpinc.ACE.POLVO | GH2: percpinc.ARIEL.LIQUIDO | GI2: percpinc.ARIEL.POLVO | GJ2: percpinc.BOLD.POLVO | GK2: percpinc.ML.POLVO | GL2: value_BA_Ace_Pwd_5to10 | GM2: value_BA_Ace_Pwd_10to15 | GN2: value_BA_Ace_Pwd_15to20 | GO2: value_BA_Ace_Pwd_20to25 | GP2: value_BA_Ace_Pwd_25to30 | GQ2: value_BA_Ace_Pwd_gt30 | GR2: xmas_dummy | GS2: flyer_percdisc.ML.Pwd
A3: 200725 | B3: 2.5744763 | C3: 0 | D3: 0 | E3: 6.0803818 | F3: 1.30295 | G3: 7.8513375 | H3: 7.8513375 | I3: 0 | J3: 11.034825 | K3: 8.46975 | L3: 0 | M3: 0 | N3: 0 | O3: 0 | P3: 0 | Q3: 0 | R3: 0 | S3: 0 | T3: 0 | U3: 0 | V3: 392739.28 | W3: 0 | X3: 0 | Y3: 689349.78 | Z3: 295632.49 | AA3: 1147098.6 | AB3: 1147098.6 | AC3: 0 | AD3: 1714147.7 | AE3: 1189066.2 | AF3: 0 | AG3: 0 | AH3: 0 | AI3: 0 | AJ3: 0 | AK3: 0 | AL3: 0 | AM3: 0 | AN3: 0 | AO3: 0 | AP3: 0 | AQ3: 0 | AR3: 0 | AS3: 0 | AT3: 0 | AU3: 0 | AV3: 0 | AW3: 0 | AX3: 0 | AY3: 0 | AZ3: 1 | BA3: 2 | BB3: 0 | BC3: 1 | BD3: 0 | BE3: 0 | BF3: 0 | BG3: 1 | BH3: 0 | BI3: 2 | BJ3: 1 | BK3: 0 | BL3: 1 | BM3: 1 | BN3: 0 | BO3: 0 | BP3: 0 | BQ3: 0 | BR3: 0 | BS3: 0 | BT3: 0 | BU3: 0 | BV3: 0 | BW3: 0 | BX3: 0 | BY3: 0 | BZ3: 0 | CA3: 0 | CB3: 0 | CC3: 0 | CD3: 0 | CE3: 0 | CF3: 0 | CG3: 0 | CH3: 0 | CI3: 0 | CJ3: 0 | CK3: 0 | CL3: 0 | CM3: 0 | CN3: 0 | CO3: 0 | CP3: 0 | CQ3: 0 | CR3: 0 | CS3: 0 | CT3: 0 | CU3: 0 | CV3: =IF(CU3<15, CU3, 0) -> 0 | CW3: =IF(CU3>15, CU3, 0) -> 0 | CX3: 0 | CY3: 0 | CZ3: =IF((CY3>10)*(CY3<=12),CY3,0) -> 0 | DA3: =IF((CY3>12)*(CY3<=14),CY3,0) -> 0 | DB3: =IF(CY3<10, 0, CY3) -> 0 | DC3: 0 | DD3: 0 | DE3: 0 | DF3: 0 | DG3: 0 | DH3: 2686936.5 | DI3: 295632.49 | DJ3: 1714147.7 | DK3: 1189066.2 | DL3: 689349.78 | DM3: 0 | DN3: 18.277151 | DO3: 1.30295 | DP3: 11.034825 | DQ3: 8.46975 | DR3: 6.0803818 | DS3: 18.277151 | DT3: 11.034825 | DU3: 8.46975 | DV3: 6.0803818 | DW3: 0 | DX3: 1.30295 | DY3: 0 | DZ3: 11.37 | EA3: 0 | EB3: 11.19 | EC3: 8.91 | ED3: 0 | EE3: 0 | EF3: 13.17 | EG3: 0 | EH3: 11.86 | EI3: 11.65 | EJ3: 0 | EK3: =AVERAGE(DZ3, EF3) -> 12.27 | EL3: 0 | EM3: 147010.68 | EN3: 226894.73 | EO3: 155339.82 | EP3: 140389.77 | EQ3: 113372.78 | ER3: 0 | ES3: 1.0566567 | ET3: 0.95496305 | EU3: 0.77118736 | EV3: 0 | EW3: 0.94638116 | EX3: 0.90375904 | EY3: 0.72983719 | EZ3: 1.0471609 | FA3: 1.1064896 | FB3: 0.80755728 | FC3: 1.2967018 | FD3: 1.3701686 | FE3: 1.2383023 | FF3: 0 | FG3: 0 | FH3: 0 | FI3: 0 | FJ3: 0 | FK3: 0 | FL3: 0 | FM3: 0 | FN3: 0 | FO3: 0 | FP3: 0 | FQ3: 0 | FR3: 0 | FS3: 0 | FT3: 0 | FU3: 0 | FV3: 0 | FW3: 0 | FX3: 0 | FY3: 0 | FZ3: 0 | GA3: 0 | GB3: 0 | GC3: 0 | GD3: 0 | GE3: 0 | GF3: 0 | GG3: 0 | GH3: 0 | GI3: 0 | GJ3: 0 | GK3: 0 | GL3: 0 | GM3: 11.37 | GN3: 0 | GO3: 0 | GP3: 0 | GQ3: 0 | GR3: 0 | GS3: 0
A4: 200726 | B4: 2.7285187 | C4: 0 | D4: 0 | E4: 7.0952162 | F4: 1.57895 | G4: 9.5772 | H4: 9.5772 | I4: 0 | J4: 13.325625 | K4: 8.043675 | L4: 0 | M4: 0 | N4: 0 | O4: 0 | P4: 0 | Q4: 0 | R4: 0 | S4: 0 | T4: 0 | U4: 0 | V4: 416111.79 | W4: 0 | X4: 0 | Y4: 806254.49 | Z4: 359090.02 | AA4: 1386238.8 | AB4: 1386238.8 | AC4: 0 | AD4: 2039151.7 | AE4: 1121467.3 | AF4: 0 | AG4: 0 | AH4: 0 | AI4: 0 | AJ4: 0 | AK4: 0 | AL4: 0 | AM4: 0 | AN4: 0 | AO4: 0 | AP4: 0 | AQ4: 0 | AR4: 0 | AS4: 0 | AT4: 0 | AU4: 0 | AV4: 0 | AW4: 0 | AX4: 0 | AY4: 0 | AZ4: 1 | BA4: 2 | BB4: 0 | BC4: 1 | BD4: 0 | BE4: 0 | BF4: 0 | BG4: 1 | BH4: 0 | BI4: 2 | BJ4: 1 | BK4: 0 | BL4: 1 | BM4: 1 | BN4: 0 | BO4: 0 | BP4: 0 | BQ4: 0 | BR4: 0 | BS4: 0 | BT4: 0 | BU4: 0 | BV4: 0 | BW4: 0 | BX4: 0 | BY4: 0 | BZ4: 0 | CA4: 0 | CB4: 0 | CC4: 0 | CD4: 0 | CE4: 0 | CF4: 0 | CG4: 0 | CH4: 0 | CI4: 0 | CJ4: 0 | CK4: 0 | CL4: 0 | CM4: 0 | CN4: 0 | CO4: 0 | CP4: 0 | CQ4: 0 | CR4: 0 | CS4: 0 | CT4: 0 | CU4: 0 | CV4: =IF(CU4<15, CU4, 0) -> 0 | CW4: =IF(CU4>15, CU4, 0) -> 0 | CX4: 0 | CY4: 0 | CZ4: =IF((CY4>10)*(CY4<=12),CY4,0) -> 0 | DA4: =IF((CY4>12)*(CY4<=14),CY4,0) -> 0 | DB4: =IF(CY4<10, 0, CY4) -> 0 | DC4: 0 | DD4: 0 | DE4: 0 | DF4: 0 | DG4: 0 | DH4: 3188589.5 | DI4: 359090.02 | DJ4: 2039151.7 | DK4: 1121467.3 | DL4: 806254.49 | DM4: 0 | DN4: 21.882919 | DO4: 1.57895 | DP4: 13.325625 | DQ4: 8.043675 | DR4: 7.0952162 | DS4: 21.882919 | DT4: 13.325625 | DU4: 8.043675 | DV4: 7.0952162 | DW4: 0 | DX4: 1.57895 | DY4: 0 | DZ4: 14.13 | EA4: 0 | EB4: 12.55 | EC4: 9.25 | ED4: 0 | EE4: 0 | EF4: 14.17 | EG4: 0 | EH4: 12.41 | EI4: 12.9 | EJ4: 0 | EK4: =AVERAGE(DZ4, EF4) -> 14.15 | EL4: 0 | EM4: 145711.34 | EN4: 227423.3 | EO4: 153024.84 | EP4: 139422.25 | EQ4: 113633.53 | ER4: 0 | ES4: 1.0501917 | ET4: 0.95683871 | EU4: 0.77985373 | EV4: 0 | EW4: 0.95220709 | EX4: 0.9111086 | EY4: 0.74258225 | EZ4: 1.0451082 | FA4: 1.097564 | FB4: 0.81503155 | FC4: 1.2822917 | FD4: 1.3466522 | FE4: 1.2269464 | FF4: 0 | FG4: 0 | FH4: 0 | FI4: 0 | FJ4: 0 | FK4: 0 | FL4: 0 | FM4: 0 | FN4: 0 | FO4: 0 | FP4: 0 | FQ4: 0 | FR4: 0 | FS4: 0 | FT4: 0 | FU4: 0 | FV4: 0 | FW4: 0 | FX4: 0 | FY4: 0 | FZ4: 0 | GA4: 0 | GB4: 0 | GC4: 0 | GD4: 0 | GE4: 0 | GF4: 0 | GG4: 0 | GH4: 0 | GI4: 0 | GJ4: 0 | GK4: 0 | GL4: 0 | GM4: 14.13 | GN4: 0 | GO4: 0 | GP4: 0 | GQ4: 0 | GR4: 0 | GS4: 0
A5: 200727 | B5: 2.5613663 | C5: 0 | D5: 0 | E5: 7.0885081 | F5: 1.5824 | G5: 9.49785 | H5: 9.49785 | I5: 0 | J5: 12.58905 | K5: 7.6521 | L5: 0 | M5: 0 | N5: 0 | O5: 0 | P5: 0 | Q5: 0 | R5: 0 | S5: 0 | T5: 0 | U5: 0 | V5: 390619.87 | W5: 0 | X5: 0 | Y5: 805562.46 | Z5: 359735.21 | AA5: 1407856.4 | AB5: 1407856.4 | AC5: 0 | AD5: 1983657.3 | AE5: 1087351.9 | AF5: 0 | AG5: 0 | AH5: 0 | AI5: 0 | AJ5: 0 | AK5: 0 | AL5: 0 | AM5: 0 | AN5: 0 | AO5: 0 | AP5: 0 | AQ5: 0 | AR5: 0 | AS5: 0 | AT5: 0 | AU5: 0 | AV5: 0 | AW5: 0 | AX5: 0 | AY5: 0 | AZ5: 1 | BA5: 2 | BB5: 0 | BC5: 1 | BD5: 0 | BE5: 0 | BF5: 0 | BG5: 1 | BH5: 0 | BI5: 2 | BJ5: 1 | BK5: 0 | BL5: 1 | BM5: 1 | BN5: 0 | BO5: 0 | BP5: 0 | BQ5: 0 | BR5: 0 | BS5: 0 | BT5: 0 | BU5: 0 | BV5: 0 | BW5: 0 | BX5: 0 | BY5: 0 | BZ5: 0 | CA5: 0 | CB5: 0 | CC5: 0 | CD5: 0 | CE5: 0 | CF5: 0 | CG5: 0 | CH5: 0 | CI5: 0 | CJ5: 0 | CK5: 0 | CL5: 0 | CM5: 0 | CN5: 0 | CO5: 0 | CP5: 0 | CQ5: 0 | CR5: 0 | CS5: 0 | CT5: 0 | CU5: 0 | CV5: =IF(CU5<15, CU5, 0) -> 0 | CW5: =IF(CU5>15, CU5, 0) -> 0 | CX5: 0 | CY5: 0 | CZ5: =IF((CY5>10)*(CY5<=12),CY5,0) -> 0 | DA5: =IF((CY5>12)*(CY5<=14),CY5,0) -> 0 | DB5: =IF(CY5<10, 0, CY5) -> 0 | DC5: 0 | DD5: 0 | DE5: 0 | DF5: 0 | DG5: 0 | DH5: 3206332.6 | DI5: 359735.21 | DJ5: 1983657.3 | DK5: 1087351.9 | DL5: 805562.46 | DM5: 0 | DN5: 21.557066 | DO5: 1.5824 | DP5: 12.58905 | DQ5: 7.6521 | DR5: 7.0885081 | DS5: 21.557066 | DT5: 12.58905 | DU5: 7.6521 | DV5: 7.0885081 | DW5: 0 | DX5: 1.5824 | DY5: 0 | DZ5: 15.28 | EA5: 0 | EB5: 12.31 | EC5: 8.62 | ED5: 0 | EE5: 0 | EF5: 14.62 | EG5: 0 | EH5: 11.61 | EI5: 11.79 | EJ5: 0 | EK5: =AVERAGE(DZ5, EF5) -> 14.95 | EL5: 0 | EM5: 148736.96 | EN5: 227335.2 | EO5: 157570.06 | EP5: 142098.49 | EQ5: 113643.44 | ER5: 0 | ES5: 1.0593873 | ET5: 0.95536769 | EU5: 0.76405648 | EV5: 0 | EW5: 0.9439418 | EX5: 0.9018115 | EY5: 0.72122486 | EZ5: 1.0467174 | FA5: 1.1088792 | FB5: 0.79975123 | FC5: 1.3088038 | FD5: 1.3865301 | FE5: 1.2503888 | FF5: 0 | FG5: 0 | FH5: 0 | FI5: 0 | FJ5: 0 | FK5: 0 | FL5: 0 | FM5: 0 | FN5: 0 | FO5: 0 | FP5: 0 | FQ5: 0 | FR5: 0 | FS5: 0 | FT5: 0 | FU5: 0 | FV5: 0 | FW5: 0 | FX5: 0 | FY5: 0 | FZ5: 0 | GA5: 0 | GB5: 0 | GC5: 0 | GD5: 0 | GE5: 0 | GF5: 0 | GG5: 0 | GH5: 0 | GI5: 0 | GJ5: 0 | GK5: 0 | GL5: 0 | GM5: 0 | GN5: 15.28 | GO5: 0 | GP5: 0 | GQ5: 0 | GR5: 0 | GS5: 0
A6: 200728 | B6: 2.93664 | C6: 0 | D6: 0 | E6: 7.0405934 | F6: 1.66635 | G6: 9.5849625 | H6: 9.5849625 | I6: 0 | J6: 13.402387 | K6: 8.0876625 | L6: 0 | M6: 0 | N6: 0 | O6: 0 | P6: 0 | Q6: 0 | R6: 0 | S6: 0 | T6: 0 | U6: 0 | V6: 447737.96 | W6: 0 | X6: 0 | Y6: 816449.28 | Z6: 379693.28 | AA6: 1412496.4 | AB6: 1412496.4 | AC6: 0 | AD6: 2110418 | AE6: 1146327.9 | AF6: 0 | AG6: 0 | AH6: 0 | AI6: 0 | AJ6: 0 | AK6: 0 | AL6: 0 | AM6: 0 | AN6: 0 | AO6: 0 | AP6: 0 | AQ6: 0 | AR6: 0 | AS6: 0 | AT6: 0 | AU6: 0 | AV6: 0 | AW6: 0 | AX6: 0 | AY6: 1 | AZ6: 1 | BA6: 2 | BB6: 0 | BC6: 1 | BD6: 0 | BE6: 2 | BF6: 0 | BG6: 0 | BH6: 0 | BI6: 2 | BJ6: 1 | BK6: 0 | BL6: 1 | BM6: 1 | BN6: 0 | BO6: 0 | BP6: 0 | BQ6: 0 | BR6: 0 | BS6: 0 | BT6: 0 | BU6: 0 | BV6: 0 | BW6: 0 | BX6: 0 | BY6: 0 | BZ6: 0 | CA6: 0 | CB6: 0 | CC6: 0 | CD6: 0 | CE6: 0 | CF6: 0 | CG6: 0 | CH6: 0 | CI6: 0 | CJ6: 0 | CK6: 0 | CL6: 0 | CM6: 0 | CN6: 0 | CO6: 0 | CP6: 0 | CQ6: 0 | CR6: 0 | CS6: 0 | CT6: 0 | CU6: 0 | CV6: =IF(CU6<15, CU6, 0) -> 0 | CW6: =IF(CU6>15, CU6, 0) -> 0 | CX6: 0 | CY6: 0 | CZ6: =IF((CY6>10)*(CY6<=12),CY6,0) -> 0 | DA6: =IF((CY6>12)*(CY6<=14),CY6,0) -> 0 | DB6: =IF(CY6<10, 0, CY6) -> 0 | DC6: 0 | DD6: 0 | DE6: 0 | DF6: 0 | DG6: 0 | DH6: 3272730.7 | DI6: 379693.28 | DJ6: 2110418 | DK6: 1146327.9 | DL6: 816449.28 | DM6: 0 | DN6: 22.106565 | DO6: 1.66635 | DP6: 13.402387 | DQ6: 8.0876625 | DR6: 7.0405934 | DS6: 22.106565 | DT6: 13.402387 | DU6: 8.0876625 | DV6: 7.0405934 | DW6: 0 | DX6: 1.66635 | DY6: 0 | DZ6: 14.07 | EA6: 0 | EB6: 11.49 | EC6: 6.28 | ED6: 0 | EE6: 0 | EF6: 14.04 | EG6: 0 | EH6: 10.41 | EI6: 9.72 | EJ6: 0 | EK6: =AVERAGE(DZ6, EF6) -> 14.055 | EL6: 0 | EM6: 148043.38 | EN6: 227859.26 | EO6: 157465.83 | EP6: 141737.86 | EQ6: 115963.14 | ER6: 0 | ES6: 1.0636465 | ET6: 0.95740756 | EU6: 0.78330509 | EV6: 0 | EW6: 0.94016198 | EX6: 0.90011818 | EY6: 0.73643366 | EZ6: 1.0444873 | FA6: 1.1109652 | FB6: 0.81815219 | FC6: 1.2766418 | FD6: 1.3578956 | FE6: 1.2222665 | FF6: 0 | FG6: 0 | FH6: 0 | FI6: 0 | FJ6: 0 | FK6: 0 | FL6: 0 | FM6: 0 | FN6: 0 | FO6: 0 | FP6: 0 | FQ6: 0 | FR6: 0 | FS6: 0 | FT6: 0 | FU6: 0 | FV6: 0 | FW6: 0 | FX6: 0 | FY6: 0 | FZ6: 0 | GA6: 0 | GB6: 0 | GC6: 0 | GD6: 0 | GE6: 0 | GF6: 0 | GG6: 0 | GH6: 0 | GI6: 0 | GJ6: 0 | GK6: 0 | GL6: 0 | GM6: 14.07 | GN6: 0 | GO6: 0 | GP6: 0 | GQ6: 0 | GR6: 0 | GS6: 0
A7: 200729 | B7: 2.2762238 | C7: 0 | D7: 0 | E7: 5.9347209 | F7: 1.60195 | G7: 8.9656875 | H7: 8.9656875 | I7: 0 | J7: 12.721012 | K7: 7.874625 | L7: 0 | M7: 0 | N7: 0 | O7: 0 | P7: 0 | Q7: 0 | R7: 0 | S7: 0 | T7: 0 | U7: 0 | V7: 347081.56 | W7: 0 | X7: 0 | Y7: 687844.9 | Z7: 366176.54 | AA7: 1318994.3 | AB7: 1318994.3 | AC7: 0 | AD7: 2000827.1 | AE7: 1117834.3 | AF7: 0 | AG7: 0 | AH7: 0 | AI7: 0 | AJ7: 0 | AK7: 0 | AL7: 0 | AM7: 0 | AN7: 0 | AO7: 0 | AP7: 0 | AQ7: 0 | AR7: 0 | AS7: 0 | AT7: 0 | AU7: 0 | AV7: 0 | AW7: 0 | AX7: 0 | AY7: 1 | AZ7: 1 | BA7: 2 | BB7: 0 | BC7: 1 | BD7: 0 | BE7: 2 | BF7: 0 | BG7: 0 | BH7: 0 | BI7: 2 | BJ7: 1 | BK7: 0 | BL7: 1 | BM7: 1 | BN7: 0 | BO7: 0 | BP7: 0 | BQ7: 0 | BR7: 0 | BS7: 0 | BT7: 0 | BU7: 0 | BV7: 0 | BW7: 0 | BX7: 0 | BY7: 0 | BZ7: 0 | CA7: 0 | CB7: 0 | CC7: 0 | CD7: 0 | CE7: 0 | CF7: 0 | CG7: 0 | CH7: 0 | CI7: 0 | CJ7: 0 | CK7: 0 | CL7: 0 | CM7: 0 | CN7: 0 | CO7: 0 | CP7: 0 | CQ7: 0 | CR7: 0 | CS7: 0 | CT7: 0 | CU7: 0 | CV7: =IF(CU7<15, CU7, 0) -> 0 | CW7: =IF(CU7>15, CU7, 0) -> 0 | CX7: 0 | CY7: 0 | CZ7: =IF((CY7>10)*(CY7<=12),CY7,0) -> 0 | DA7: =IF((CY7>12)*(CY7<=14),CY7,0) -> 0 | DB7: =IF(CY7<10, 0, CY7) -> 0 | DC7: 0 | DD7: 0 | DE7: 0 | DF7: 0 | DG7: 0 | DH7: 2985070.2 | DI7: 366176.54 | DJ7: 2000827.1 | DK7: 1117834.3 | DL7: 687844.9 | DM7: 0 | DN7: 20.207599 | DO7: 1.60195 | DP7: 12.721012 | DQ7: 7.874625 | DR7: 5.9347209 | DS7: 20.207599 | DT7: 12.721012 | DU7: 7.874625 | DV7: 5.9347209 | DW7: 0 | DX7: 1.60195 | DY7: 0 | DZ7: 14.21 | EA7: 0 | EB7: 12.01 | EC7: 7.07 | ED7: 0 | EE7: 0 | EF7: 14.92 | EG7: 0 | EH7: 11.64 | EI7: 10.28 | EJ7: 0 | EK7: =AVERAGE(DZ7, EF7) -> 14.565 | EL7: 0 | EM7: 147720.18 | EN7: 228581.75 | EO7: 157285.21 | EP7: 141953.97 | EQ7: 115901.81 | ER7: 0 | ES7: 1.064751 | ET7: 0.96096533 | EU7: 0.78460375 | EV7: 0 | EW7: 0.93918673 | EX7: 0.90252588 | EY7: 0.73688943 | EZ7: 1.0406203 | FA7: 1.1080015 | FB7: 0.81647457 | FC7: 1.2745287 | FD7: 1.3570557 | FE7: 1.2247779 | FF7: 0 | FG7: 0 | FH7: 0 | FI7: 0 | FJ7: 0 | FK7: 0 | FL7: 0 | FM7: 0 | FN7: 0 | FO7: 0 | FP7: 0 | FQ7: 0 | FR7: 0 | FS7: 0 | FT7: 0 | FU7: 0 | FV7: 0 | FW7: 0 | FX7: 0 | FY7: 0 | FZ7: 0 | GA7: 0 | GB7: 0 | GC7: 0 | GD7: 0 | GE7: 0 | GF7: 0 | GG7: 0 | GH7: 0 | GI7: 0 | GJ7: 0 | GK7: 0 | GL7: 0 | GM7: 14.21 | GN7: 0 | GO7: 0 | GP7: 0 | GQ7: 0 | GR7: 0 | GS7: 0
A8: 200730 | B8: 1.3683563 | C8: 0 | D8: 0 | E8: 5.9356792 | F8: 1.44095 | G8: 7.8892875 | H8: 7.8892875 | I8: 0 | J8: 18.020212 | K8: 6.6490125 | L8: 0 | M8: 0 | N8: 0 | O8: 0 | P8: 0 | Q8: 0 | R8: 0 | S8: 0 | T8: 0 | U8: 0 | V8: 208477.76 | W8: 0 | X8: 0 | Y8: 686132.61 | Z8: 332141.63 | AA8: 1162630.9 | AB8: 1162630.9 | AC8: 0 | AD8: 2675222.3 | AE8: 944891.97 | AF8: 0 | AG8: 0 | AH8: 0 | AI8: 0 | AJ8: 0 | AK8: 0 | AL8: 0 | AM8: 0 | AN8: 0 | AO8: 0 | AP8: 0 | AQ8: 0 | AR8: 0 | AS8: 0 | AT8: 0 | AU8: 0 | AV8: 0 | AW8: 0 | AX8: 0 | AY8: 1 | AZ8: 1 | BA8: 2 | BB8: 0 | BC8: 1 | BD8: 0 | BE8: 2 | BF8: 0 | BG8: 0 | BH8: 0 | BI8: 2 | BJ8: 1 | BK8: 0 | BL8: 1 | BM8: 1 | BN8: 0 | BO8: 0 | BP8: 0 | BQ8: 0 | BR8: 0 | BS8: 0 | BT8: 0 | BU8: 0 | BV8: 0 | BW8: 0 | BX8: 0 | BY8: 0 | BZ8: 0 | CA8: 0 | CB8: 0 | CC8: 0 | CD8: 0 | CE8: 0 | CF8: 0 | CG8: 0 | CH8: 0 | CI8: 0 | CJ8: 0 | CK8: 0 | CL8: 0 | CM8: 0 | CN8: 0 | CO8: 0 | CP8: 0 | CQ8: 0 | CR8: 0 | CS8: 0 | CT8: 0 | CU8: 0 | CV8: =IF(CU8<15, CU8, 0) -> 0 | CW8: =IF(CU8>15, CU8, 0) -> 0 | CX8: 0 | CY8: 0 | CZ8: =IF((CY8>10)*(CY8<=12),CY8,0) -> 0 | DA8: =IF((CY8>12)*(CY8<=14),CY8,0) -> 0 | DB8: =IF(CY8<10, 0, CY8) -> 0 | DC8: 0 | DD8: 0 | DE8: 0 | DF8: 0 | DG8: 0 | DH8: 2533739.5 | DI8: 332141.63 | DJ8: 2675222.3 | DK8: 944891.97 | DL8: 686132.61 | DM8: 0 | DN8: 17.146931 | DO8: 1.44095 | DP8: 18.020212 | DQ8: 6.6490125 | DR8: 5.9356792 | DS8: 17.146931 | DT8: 18.020212 | DU8: 6.6490125 | DV8: 5.9356792 | DW8: 0 | DX8: 1.44095 | DY8: 0 | DZ8: 13.11 | EA8: 0 | EB8: 10.3 | EC8: 5.95 | ED8: 0 | EE8: 0 | EF8: 15.56 | EG8: 0 | EH8: 12.72 | EI8: 10.23 | EJ8: 0 | EK8: =AVERAGE(DZ8, EF8) -> 14.335 | EL8: 0 | EM8: 147766.35 | EN8: 230501.84 | EO8: 148456.75 | EP8: 142110.12 | EQ8: 115594.62 | ER8: 0 | ES8: 1.0046723 | ET8: 0.9617218 | EU8: 0.78227975 | EV8: 0 | EW8: 0.99534947 | EX8: 0.95724928 | EY8: 0.77864173 | EZ8: 1.0398017 | FA8: 1.04466 | FB8: 0.81341584 | FC8: 1.2783151 | FD8: 1.2842877 | FE8: 1.2293835 | FF8: 0 | FG8: 0 | FH8: 0 | FI8: 0 | FJ8: 0 | FK8: 0 | FL8: 0 | FM8: 0 | FN8: 0 | FO8: 0 | FP8: 0 | FQ8: 0 | FR8: 0 | FS8: 0 | FT8: 0 | FU8: 0 | FV8: 0 | FW8: 0 | FX8: 0 | FY8: 0 | FZ8: 0 | GA8: 0 | GB8: 0 | GC8: 0 | GD8: 0 | GE8: 0 | GF8: 0 | GG8: 0 | GH8: 0 | GI8: 0 | GJ8: 0 | GK8: 0 | GL8: 0 | GM8: 13.11 | GN8: 0 | GO8: 0 | GP8: 0 | GQ8: 0 | GR8: 0 | GS8: 0
A9: 200731 | B9: 1.14057 | C9: 0 | D9: 0 | E9: 7.2782505 | F9: 1.72385 | G9: 8.9915625 | H9: 8.9915625 | I9: 0 | J9: 19.51665 | K9: 7.5856875 | L9: 0 | M9: 0 | N9: 0 | O9: 0 | P9: 0 | Q9: 0 | R9: 0 | S9: 0 | T9: 0 | U9: 0 | V9: 170974.02 | W9: 0 | X9: 0 | Y9: 841348.82 | Z9: 397427.09 | AA9: 1322498.4 | AB9: 1322498.4 | AC9: 0 | AD9: 2895625.4 | AE9: 1080375.8 | AF9: 0 | AG9: 0 | AH9: 0 | AI9: 0 | AJ9: 0 | AK9: 0 | AL9: 0 | AM9: 0 | AN9: 0 | AO9: 0 | AP9: 0 | AQ9: 0 | AR9: 0 | AS9: 0 | AT9: 0 | AU9: 0 | AV9: 0 | AW9: 0 | AX9: 0 | AY9: 1 | AZ9: 1 | BA9: 2 | BB9: 0 | BC9: 1 | BD9: 0 | BE9: 2 | BF9: 0 | BG9: 0 | BH9: 0 | BI9: 2 | BJ9: 1 | BK9: 0 | BL9: 1 | BM9: 1 | BN9: 0 | BO9: 0 | BP9: 0 | BQ9: 0 | BR9: 0 | BS9: 0 | BT9: 0 | BU9: 0 | BV9: 0 | BW9: 0 | BX9: 0 | BY9: 0 | BZ9: 0 | CA9: 0 | CB9: 0 | CC9: 0 | CD9: 0 | CE9: 0 | CF9: 0 | CG9: 0 | CH9: 0 | CI9: 0 | CJ9: 0 | CK9: 0 | CL9: 0 | CM9: 0 | CN9: 0 | CO9: 0 | CP9: 0 | CQ9: 0 | CR9: 0 | CS9: 0 | CT9: 0 | CU9: 0 | CV9: =IF(CU9<15, CU9, 0) -> 0 | CW9: =IF(CU9>15, CU9, 0) -> 0 | CX9: 0 | CY9: 0 | CZ9: =IF((CY9>10)*(CY9<=12),CY9,0) -> 0 | DA9: =IF((CY9>12)*(CY9<=14),CY9,0) -> 0 | DB9: =IF(CY9<10, 0, CY9) -> 0 | DC9: 0 | DD9: 0 | DE9: 0 | DF9: 0 | DG9: 0 | DH9: 2815970.8 | DI9: 397427.09 | DJ9: 2895625.4 | DK9: 1080375.8 | DL9: 841348.82 | DM9: 0 | DN9: 19.123695 | DO9: 1.72385 | DP9: 19.51665 | DQ9: 7.5856875 | DR9: 7.2782505 | DS9: 19.123695 | DT9: 19.51665 | DU9: 7.5856875 | DV9: 7.2782505 | DW9: 0 | DX9: 1.72385 | DY9: 0 | DZ9: 13.19 | EA9: 0 | EB9: 16.27 | EC9: 5.76 | ED9: 0 | EE9: 0 | EF9: 15.09 | EG9: 0 | EH9: 18.51 | EI9: 9.77 | EJ9: 0 | EK9: =AVERAGE(DZ9, EF9) -> 14.14 | EL9: 0 | EM9: 147250.35 | EN9: 230546.21 | EO9: 148366.93 | EP9: 142422.93 | EQ9: 115597.67 | ER9: 0 | ES9: 1.0075829 | ET9: 0.96721626 | EU9: 0.78504176 | EV9: 0 | EW9: 0.9924742 | EX9: 0.95993718 | EY9: 0.77913369 | EZ9: 1.0338949 | FA9: 1.0417348 | FB9: 0.8116507 | FC9: 1.2738176 | FD9: 1.2834768 | FE9: 1.2320571 | FF9: 0 | FG9: 0 | FH9: 0 | FI9: 0 | FJ9: 0 | FK9: 0 | FL9: 0 | FM9: 0 | FN9: 0 | FO9: 0 | FP9: 0 | FQ9: 0 | FR9: 0 | FS9: 0 | FT9: 0 | FU9: 0 | FV9: 0 | FW9: 0 | FX9: 0 | FY9: 0 | FZ9: 0 | GA9: 0 | GB9: 0 | GC9: 0 | GD9: 0 | GE9: 0 | GF9: 0 | GG9: 0 | GH9: 0 | GI9: 0 | GJ9: 0 | GK9: 0 | GL9: 0 | GM9: 13.19 | GN9: 0 | GO9: 0 | GP9: 0 | GQ9: 0 | GR9: 0 | GS9: 0
A10: 200732 | B10: 0.80790375 | C10: 0 | D10: 0 | E10: 6.3113309 | F10: 1.5525 | G10: 8.133375 | H10: 8.133375 | I10: 0 | J10: 15.424087 | K10: 7.129425 | L10: 0 | M10: 0 | N10: 0 | O10: 0 | P10: 0 | Q10: 0 | R10: 0 | S10: 0 | T10: 0 | U10: 0 | V10: 104219.85 | W10: 0 | X10: 0 | Y10: 731061.23 | Z10: 356948.41 | AA10: 1207575.5 | AB10: 1207575.5 | AC10: 0 | AD10: 2291209.3 | AE10: 1012407.8 | AF10: 0 | AG10: 0 | AH10: 0 | AI10: 0 | AJ10: 0 | AK10: 0 | AL10: 0 | AM10: 0 | AN10: 0 | AO10: 0 | AP10: 0 | AQ10: 0 | AR10: 0 | AS10: 0 | AT10: 0 | AU10: 0 | AV10: 0 | AW10: 0 | AX10: 0 | AY10: 1 | AZ10: 0 | BA10: 2 | BB10: 0 | BC10: 1 | BD10: 0 | BE10: 2 | BF10: 0 | BG10: 1 | BH10: 0 | BI10: 2 | BJ10: 0 | BK10: 0 | BL10: 1 | BM10: 1 | BN10: 0 | BO10: 0 | BP10: 0 | BQ10: 0 | BR10: 0 | BS10: 0 | BT10: 0 | BU10: 0 | BV10: 0 | BW10: 0 | BX10: 0 | BY10: 0 | BZ10: 0 | CA10: 0 | CB10: 0 | CC10: 0 | CD10: 0 | CE10: 0 | CF10: 0 | CG10: 0 | CH10: 0 | CI10: 0 | CJ10: 0 | CK10: 15.02 | CL10: 0 | CM10: 0 | CN10: 0 | CO10: 0 | CP10: 0 | CQ10: 0 | CR10: 0 | CS10: 0 | CT10: 0 | CU10: 0 | CV10: =IF(CU10<15, CU10, 0) -> 0 | CW10: =IF(CU10>15, CU10, 0) -> 0 | CX10: 0 | CY10: 0 | CZ10: =IF((CY10>10)*(CY10<=12),CY10,0) -> 0 | DA10: =IF((CY10>12)*(CY10<=14),CY10,0) -> 0 | DB10: =IF(CY10<10, 0, CY10) -> 0 | DC10: 0 | DD10: 0 | DE10: 0 | DF10: 0 | DG10: 0 | DH10: 2519370.9 | DI10: 356948.41 | DJ10: 2291209.3 | DK10: 1012407.8 | DL10: 731061.23 | DM10: 0 | DN10: 17.074654 | DO10: 1.5525 | DP10: 15.424087 | DQ10: 7.129425 | DR10: 6.3113309 | DS10: 17.074654 | DT10: 15.424087 | DU10: 7.129425 | DV10: 6.3113309 | DW10: 0 | DX10: 1.5525 | DY10: 0 | DZ10: 14.09 | EA10: 0 | EB10: 17 | EC10: 6 | ED10: 0 | EE10: 0 | EF10: 14.6 | EG10: 0 | EH10: 18.14 | EI10: 8.93 | EJ10: 0 | EK10: =AVERAGE(DZ10, EF10) -> 14.345 | EL10: 0 | EM10: 147550.34 | EN10: 229918.46 | EO10: 148547.48 | EP10: 142004.13 | EQ10: 115833.13 | ER10: 0 | ES10: 1.006758 | ET10: 0.9624114 | EU10: 0.78504146 | EV10: 0 | EW10: 0.99328738 | EX10: 0.9559511 | EY10: 0.77977178 | EZ10: 1.0390567 | FA10: 1.0460786 | FB10: 0.81570258 | FC10: 1.2738181 | FD10: 1.2824265 | FE10: 1.225937 | FF10: 0 | FG10: 0 | FH10: 0 | FI10: 0 | FJ10: 0 | FK10: 0 | FL10: 0 | FM10: 0 | FN10: 0 | FO10: 0 | FP10: 0 | FQ10: 0 | FR10: 0 | FS10: 0 | FT10: 0 | FU10: 0 | FV10: 0 | FW10: 0 | FX10: 0 | FY10: 0 | FZ10: 0 | GA10: 0 | GB10: 0 | GC10: 0 | GD10: 0 | GE10: 0 | GF10: 0 | GG10: 0 | GH10: 0 | GI10: 0 | GJ10: 0 | GK10: 0 | GL10: 0 | GM10: 14.09 | GN10: 0 | GO10: 0 | GP10: 0 | GQ10: 0 | GR10: 0 | GS10: 0
A11: 200733 | B11: 0.45803062 | C11: 0 | D11: 0 | E11: 6.7454385 | F11: 1.6629 | G11: 10.749337 | H11: 10.749337 | I11: 0 | J11: 16.220175 | K11: 7.591725 | L11: 0 | M11: 0 | N11: 0 | O11: 0 | P11: 0 | Q11: 0 | R11: 0 | S11: 0 | T11: 0 | U11: 0 | V11: 60475.303 | W11: 0 | X11: 0 | Y11: 792146.66 | Z11: 384404 | AA11: 1618513 | AB11: 1618513 | AC11: 0 | AD11: 2409498.1 | AE11: 1079370.7 | AF11: 0 | AG11: 0 | AH11: 0 | AI11: 0 | AJ11: 0 | AK11: 0 | AL11: 0 | AM11: 0 | AN11: 0 | AO11: 0 | AP11: 0 | AQ11: 0 | AR11: 0 | AS11: 0 | AT11: 0 | AU11: 0 | AV11: 0 | AW11: 0 | AX11: 0 | AY11: 1 | AZ11: 0 | BA11: 2 | BB11: 0 | BC11: 1 | BD11: 0 | BE11: 2 | BF11: 0 | BG11: 1 | BH11: 0 | BI11: 2 | BJ11: 0 | BK11: 0 | BL11: 1 | BM11: 1 | BN11: 0 | BO11: 0 | BP11: 0 | BQ11: 0 | BR11: 0 | BS11: 0 | BT11: 0 | BU11: 0 | BV11: 0 | BW11: 0 | BX11: 0 | BY11: 0 | BZ11: 0 | CA11: 0 | CB11: 0 | CC11: 0 | CD11: 0 | CE11: 0 | CF11: 0 | CG11: 0 | CH11: 0 | CI11: 0 | CJ11: 0 | CK11: 12.9 | CL11: 0 | CM11: 0 | CN11: 0 | CO11: 0 | CP11: 0 | CQ11: 0 | CR11: 0 | CS11: 0 | CT11: 0 | CU11: 0 | CV11: =IF(CU11<15, CU11, 0) -> 0 | CW11: =IF(CU11>15, CU11, 0) -> 0 | CX11: 0 | CY11: 0 | CZ11: =IF((CY11>10)*(CY11<=12),CY11,0) -> 0 | DA11: =IF((CY11>12)*(CY11<=14),CY11,0) -> 0 | DB11: =IF(CY11<10, 0, CY11) -> 0 | DC11: 0 | DD11: 0 | DE11: 0 | DF11: 0 | DG11: 0 | DH11: 3297501.3 | DI11: 384404 | DJ11: 2409498.1 | DK11: 1079370.7 | DL11: 792146.66 | DM11: 0 | DN11: 21.956706 | DO11: 1.6629 | DP11: 16.220175 | DQ11: 7.591725 | DR11: 6.7454385 | DS11: 21.956706 | DT11: 16.220175 | DU11: 7.591725 | DV11: 6.7454385 | DW11: 0 | DX11: 1.6629 | DY11: 0 | DZ11: 14.41 | EA11: 0 | EB11: 17.52 | EC11: 7.61 | ED11: 0 | EE11: 0 | EF11: 15.49 | EG11: 0 | EH11: 18.33 | EI11: 10.29 | EJ11: 0 | EK11: =AVERAGE(DZ11, EF11) -> 14.95 | EL11: 0 | EM11: 150181.97 | EN11: 231164.83 | EO11: 148549.45 | EP11: 142177.26 | EQ11: 117434.42 | ER11: 0 | ES11: 0.98912974 | ET11: 0.94669994 | EU11: 0.78194753 | EV11: 0 | EW11: 1.0109897 | EX11: 0.95710392 | EY11: 0.79054091 | EZ11: 1.0563009 | FA11: 1.0448186 | FB11: 0.82597187 | FC11: 1.2788582 | FD11: 1.2649567 | FE11: 1.210695 | FF11: 0 | FG11: 0 | FH11: 0 | FI11: 0 | FJ11: 0 | FK11: 0 | FL11: 0 | FM11: 0 | FN11: 0 | FO11: 0 | FP11: 0 | FQ11: 0 | FR11: 0 | FS11: 0 | FT11: 0 | FU11: 0 | FV11: 0 | FW11: 0 | FX11: 0 | FY11: 0 | FZ11: 0 | GA11: 0 | GB11: 0 | GC11: 0 | GD11: 0 | GE11: 0 | GF11: 0 | GG11: 0 | GH11: 0 | GI11: 0 | GJ11: 0 | GK11: 0 | GL11: 0 | GM11: 14.41 | GN11: 0 | GO11: 0 | GP11: 0 | GQ11: 0 | GR11: 0 | GS11: 0
A12: 200734 | B12: 0.11962875 | C12: 0.3368925 | D12: 0 | E12: 6.9850123 | F12: 1.536975 | G12: 8.8225125 | H12: 8.8225125 | I12: 0 | J12: 14.72115 | K12: 7.574475 | L12: 0 | M12: 0 | N12: 0 | O12: 0 | P12: 0 | Q12: 0 | R12: 0 | S12: 0 | T12: 0 | U12: 0 | V12: 16819.176 | W12: 61836.88 | X12: 0 | Y12: 818233.75 | Z12: 357952.81 | AA12: 1325685 | AB12: 1325685 | AC12: 0 | AD12: 2236513.2 | AE12: 1078253.1 | AF12: 0 | AG12: 0 | AH12: 0 | AI12: 0 | AJ12: 0 | AK12: 0 | AL12: 0 | AM12: 0 | AN12: 0 | AO12: 0 | AP12: 0 | AQ12: 0 | AR12: 0 | AS12: 0 | AT12: 0 | AU12: 0 | AV12: 0 | AW12: 0 | AX12: 0 | AY12: 1 | AZ12: 0 | BA12: 2 | BB12: 0 | BC12: 1 | BD12: 0 | BE12: 2 | BF12: 0 | BG12: 1 | BH12: 0 | BI12: 2 | BJ12: 0 | BK12: 0 | BL12: 1 | BM12: 1 | BN12: 0 | BO12: 0 | BP12: 0 | BQ12: 0 | BR12: 0 | BS12: 0 | BT12: 0 | BU12: 0 | BV12: 0 | BW12: 0 | BX12: 0 | BY12: 0 | BZ12: 0 | CA12: 0 | CB12: 0 | CC12: 0 | CD12: 0 | CE12: 0 | CF12: 0 | CG12: 0 | CH12: 0 | CI12: 0 | CJ12: 0 | CK12: 0 | CL12: 0 | CM12: 0 | CN12: 0 | CO12: 0 | CP12: 0 | CQ12: 0 | CR12: 0 | CS12: 0 | CT12: 0 | CU12: 0 | CV12: =IF(CU12<15, CU12, 0) -> 0 | CW12: =IF(CU12>15, CU12, 0) -> 0 | CX12: 0 | CY12: 0 | CZ12: =IF((CY12>10)*(CY12<=12),CY12,0) -> 0 | DA12: =IF((CY12>12)*(CY12<=14),CY12,0) -> 0 | DB12: =IF(CY12<10, 0, CY12) -> 0 | DC12: 0 | DD12: 0 | DE12: 0 | DF12: 0 | DG12: 0 | DH12: 2668189.1 | DI12: 357952.81 | DJ12: 2298350.1 | DK12: 1078253.1 | DL12: 818233.75 | DM12: 0 | DN12: 17.764654 | DO12: 1.536975 | DP12: 15.058042 | DQ12: 7.574475 | DR12: 6.9850123 | DS12: 17.764654 | DT12: 15.058042 | DU12: 7.574475 | DV12: 6.9850123 | DW12: 0 | DX12: 1.536975 | DY12: 0 | DZ12: 12.56 | EA12: 0 | EB12: 20.3 | EC12: 7.56 | ED12: 0 | EE12: 0 | EF12: 14.23 | EG12: 0 | EH12: 20.99 | EI12: 9.3 | EJ12: 0 | EK12: =AVERAGE(DZ12, EF12) -> 13.395 | EL12: 0 | EM12: 150196.52 | EN12: 232894.36 | EO12: 152632.73 | EP12: 142353.5 | EQ12: 117141.35 | ER12: 0 | ES12: 1.0162201 | ET12: 0.94778166 | EU12: 0.77992054 | EV12: 0 | EW12: 0.98403875 | EX12: 0.93265388 | EY12: 0.76747203 | EZ12: 1.0550953 | FA12: 1.0722091 | FB12: 0.82289052 | FC12: 1.2821819 | FD12: 1.3029791 | FE12: 1.2152285 | FF12: 0 | FG12: 0 | FH12: 0 | FI12: 0 | FJ12: 0 | FK12: 0 | FL12: 0 | FM12: 0 | FN12: 0 | FO12: 0 | FP12: 0 | FQ12: 0 | FR12: 0 | FS12: 0 | FT12: 0 | FU12: 0 | FV12: 0 | FW12: 0 | FX12: 0 | FY12: 0 | FZ12: 0 | GA12: 0 | GB12: 0 | GC12: 0 | GD12: 0 | GE12: 0 | GF12: 0 | GG12: 0 | GH12: 0 | GI12: 0 | GJ12: 0 | GK12: 0 | GL12: 0 | GM12: 12.56 | GN12: 0 | GO12: 0 | GP12: 0 | GQ12: 0 | GR12: 0 | GS12: 0
A13: 200735 | B13: 0.053259375 | C13: 1.9072463 | D13: 0 | E13: 8.1378411 | F13: 1.831375 | G13: 10.59495 | H13: 10.59495 | I13: 0 | J13: 15.8838 | K13: 9.2046 | L13: 0 | M13: 0 | N13: 0 | O13: 0 | P13: 0 | Q13: 0 | R13: 0 | S13: 0 | T13: 0 | U13: 0 | V13: 7423.273 | W13: 341545.01 | X13: 0 | Y13: 950735.49 | Z13: 421774.78 | AA13: 1585344.7 | AB13: 1585344.7 | AC13: 0 | AD13: 2537819.8 | AE13: 1313156.4 | AF13: 0 | AG13: 0 | AH13: 0 | AI13: 0 | AJ13: 0 | AK13: 0 | AL13: 0 | AM13: 0 | AN13: 0 | AO13: 0 | AP13: 0 | AQ13: 0 | AR13: 0 | AS13: 0 | AT13: 0 | AU13: 0 | AV13: 0 | AW13: 0 | AX13: 0 | AY13: 1 | AZ13: 0 | BA13: 2 | BB13: 0 | BC13: 1 | BD13: 0 | BE13: 2 | BF13: 0 | BG13: 1 | BH13: 0 | BI13: 2 | BJ13: 0 | BK13: 0 | BL13: 1 | BM13: 1 | BN13: 0 | BO13: 0 | BP13: 0 | BQ13: 0 | BR13: 0 | BS13: 0 | BT13: 0 | BU13: 0 | BV13: 0 | BW13: 0 | BX13: 0 | BY13: 0 | BZ13: 0 | CA13: 0 | CB13: 0 | CC13: 0 | CD13: 0 | CE13: 0 | CF13: 0 | CG13: 0 | CH13: 0 | CI13: 0 | CJ13: 0 | CK13: 0 | CL13: 0 | CM13: 0 | CN13: 0 | CO13: 0 | CP13: 0 | CQ13: 0 | CR13: 0 | CS13: 0 | CT13: 0 | CU13: 0 | CV13: =IF(CU13<15, CU13, 0) -> 0 | CW13: =IF(CU13>15, CU13, 0) -> 0 | CX13: 0 | CY13: 0 | CZ13: =IF((CY13>10)*(CY13<=12),CY13,0) -> 0 | DA13: =IF((CY13>12)*(CY13<=14),CY13,0) -> 0 | DB13: =IF(CY13<10, 0, CY13) -> 0 | DC13: 0 | DD13: 0 | DE13: 0 | DF13: 0 | DG13: 0 | DH13: 3178112.7 | DI13: 421774.78 | DJ13: 2879364.8 | DK13: 1313156.4 | DL13: 950735.49 | DM13: 0 | DN13: 21.243159 | DO13: 1.831375 | DP13: 17.791046 | DQ13: 9.2046 | DR13: 8.1378411 | DS13: 21.243159 | DT13: 17.791046 | DU13: 9.2046 | DV13: 8.1378411 | DW13: 0 | DX13: 1.831375 | DY13: 0 | DZ13: 11.23 | EA13: 0 | EB13: 19.35 | EC13: 2.26 | ED13: 0 | EE13: 0 | EF13: 12.41 | EG13: 0 | EH13: 18.42 | EI13: 0.5 | EJ13: 0 | EK13: =AVERAGE(DZ13, EF13) -> 11.82 | EL13: 0 | EM13: 149606.41 | EN13: 230304.98 | EO13: 161843.48 | EP13: 142663.06 | EQ13: 116828.96 | ER13: 0 | ES13: 1.0817951 | ET13: 0.95358923 | EU13: 0.78090878 | EV13: 0 | EW13: 0.92438947 | EX13: 0.88148784 | EY13: 0.72186385 | EZ13: 1.0486696 | FA13: 1.1344456 | FB13: 0.81891526 | FC13: 1.2805593 | FD13: 1.3853028 | FE13: 1.2211276 | FF13: 0 | FG13: 0 | FH13: 0 | FI13: 0 | FJ13: 0 | FK13: 0 | FL13: 0 | FM13: 0 | FN13: 0 | FO13: 0 | FP13: 0 | FQ13: 0 | FR13: 0 | FS13: 0 | FT13: 0 | FU13: 0 | FV13: 0 | FW13: 0 | FX13: 0 | FY13: 0 | FZ13: 0 | GA13: 0 | GB13: 0 | GC13: 0 | GD13: 0 | GE13: 0 | GF13: 0 | GG13: 0 | GH13: 0 | GI13: 0 | GJ13: 0 | GK13: 0 | GL13: 0 | GM13: 11.23 | GN13: 0 | GO13: 0 | GP13: 0 | GQ13: 0 | GR13: 0 | GS13: 0
A14: 200736 | B14: 0.009013125 | C14: 2.0912175 | D14: 0 | E14: 6.9620132 | F14: 1.55135 | G14: 9.98775 | H14: 9.98775 | I14: 0 | J14: 13.593 | K14: 8.1980625 | L14: 15.701812 | M14: 0 | N14: 3.611115 | O14: 0 | P14: 0 | Q14: 0 | R14: 0 | S14: 0 | T14: 0 | U14: 0 | V14: 1051.353 | W14: 374347.38 | X14: 0 | Y14: 811324.37 | Z14: 362714.55 | AA14: 1450365.3 | AB14: 1450365.3 | AC14: 0 | AD14: 2123594.9 | AE14: 1170795.8 | AF14: 2238643.2 | AG14: 0 | AH14: 628267.79 | AI14: 0 | AJ14: 0 | AK14: 0 | AL14: 0 | AM14: 0 | AN14: 0 | AO14: 0 | AP14: 0 | AQ14: 0 | AR14: 0 | AS14: 0 | AT14: 0 | AU14: 0 | AV14: 0 | AW14: 0 | AX14: 0 | AY14: 1 | AZ14: 0 | BA14: 2 | BB14: 0 | BC14: 1 | BD14: 0 | BE14: 2 | BF14: 0 | BG14: 1 | BH14: 0 | BI14: 2 | BJ14: 0 | BK14: 0 | BL14: 1 | BM14: 1 | BN14: 0 | BO14: 0 | BP14: 0 | BQ14: 0 | BR14: 0 | BS14: 0 | BT14: 0 | BU14: 0 | BV14: 0 | BW14: 0 | BX14: 0 | BY14: 0 | BZ14: 0 | CA14: 0 | CB14: 0 | CC14: 0 | CD14: 0 | CE14: 0 | CF14: 0 | CG14: 0 | CH14: 0 | CI14: 0 | CJ14: 0 | CK14: 16.67 | CL14: 0 | CM14: 0 | CN14: 0 | CO14: 0 | CP14: 0 | CQ14: 0 | CR14: 0 | CS14: 0 | CT14: 0 | CU14: 0 | CV14: =IF(CU14<15, CU14, 0) -> 0 | CW14: =IF(CU14>15, CU14, 0) -> 0 | CX14: 0 | CY14: 0 | CZ14: =IF((CY14>10)*(CY14<=12),CY14,0) -> 0 | DA14: =IF((CY14>12)*(CY14<=14),CY14,0) -> 0 | DB14: =IF(CY14<10, 0, CY14) -> 0 | DC14: 0 | DD14: 0 | DE14: 0 | DF14: 0 | DG14: 0 | DH14: 5140425.1 | DI14: 362714.55 | DJ14: 3126210 | DK14: 1170795.8 | DL14: 811324.37 | DM14: 0 | DN14: 35.686326 | DO14: 1.55135 | DP14: 19.295332 | DQ14: 8.1980625 | DR14: 6.9620132 | DS14: 35.686326 | DT14: 19.295332 | DU14: 8.1980625 | DV14: 6.9620132 | DW14: 0 | DX14: 1.55135 | DY14: 0 | DZ14: 10.27 | EA14: 0 | EB14: 14.61 | EC14: 0.63 | ED14: 0 | EE14: 0 | EF14: 11.8 | EG14: 0 | EH14: 16.43 | EI14: 3.41 | EJ14: 0 | EK14: =AVERAGE(DZ14, EF14) -> 11.035 | EL14: 0 | EM14: 144044.67 | EN14: 233805.75 | EO14: 162018.98 | EP14: 142813.72 | EQ14: 116535.89 | ER14: 0 | ES14: 1.1247828 | ET14: 0.99145439 | EU14: 0.809026 | EV14: 0 | EW14: 0.8890605 | EX14: 0.88146294 | EY14: 0.71927306 | EZ14: 1.0086193 | FA14: 1.1344777 | FB14: 0.81599921 | FC14: 1.2360542 | FD14: 1.3902926 | FE14: 1.2254914 | FF14: 0 | FG14: 0 | FH14: 0 | FI14: 0 | FJ14: 0 | FK14: 0 | FL14: 0 | FM14: 0 | FN14: 0 | FO14: 0 | FP14: 0 | FQ14: 0 | FR14: 0 | FS14: 0 | FT14: 0 | FU14: 0 | FV14: 0 | FW14: 0 | FX14: 0 | FY14: 0 | FZ14: 0 | GA14: 0 | GB14: 0 | GC14: 0 | GD14: 0 | GE14: 0 | GF14: 0 | GG14: 0 | GH14: 0 | GI14: 0 | GJ14: 0 | GK14: 0 | GL14: 0 | GM14: 10.27 | GN14: 0 | GO14: 0 | GP14: 0 | GQ14: 0 | GR14: 0 | GS14: 0
... A105: 200923 | B105: 0 | C105: 0 | D105: 0 | E105: 10.821067 | F105: 0 | G105: 0.2527125 | H105: 0.2527125 | I105: 4.555725 | J105: 14.374425 | K105: 0 | L105: 20.698275 | M105: 0 | N105: 2.5841362 | O105: 0 | P105: 0.0549746 | Q105: 7.81218 | R105: 0 | S105: 0 | T105: 3.4659563 | U105: 4.4013375 | V105: 0 | W105: 0 | X105: 0 | Y105: 1774532 | Z105: 0 | AA105: 29055.026 | AB105: 29055.026 | AC105: 1034743 | AD105: 3169219.9 | AE105: 0 | AF105: 4230027.9 | AG105: 0 | AH105: 616150.75 | AI105: 0 | AJ105: 9996.306 | AK105: 1633974.1 | AL105: 0 | AM105: 0 | AN105: 838167.52 | AO105: 852699.1 | AP105: 0 | AQ105: 0 | AR105: 0 | AS105: 0 | AT105: 0 | AU105: 0 | AV105: 1 | AW105: 1 | AX105: 0 | AY105: 0 | AZ105: 1 | BA105: 2 | BB105: 0 | BC105: 1 | BD105: 0 | BE105: 2 | BF105: 0 | BG105: 0 | BH105: 0 | BI105: 2 | BJ105: 0 | BK105: 0 | BL105: 1 | BM105: 1 | BN105: 0 | BO105: 0 | BP105: 0 | BQ105: 0 | BR105: 0 | BS105: 0 | BT105: 0 | BU105: 0 | BV105: 0 | BW105: 0 | BX105: 0 | BY105: 0 | BZ105: 0 | CA105: 0 | CB105: 0 | CC105: 0 | CD105: 0 | CE105: 0 | CF105: 0 | CG105: 0 | CH105: 0 | CI105: 46.23 | CJ105: 0 | CK105: 0 | CL105: 46.23 | CM105: 0 | CN105: 0 | CO105: 0 | CP105: 0 | CQ105: 0 | CR105: 0 | CS105: 0 | CT105: 0 | CU105: 0 | CV105: =IF(CU105<15, CU105, 0) -> 0 | CW105: =IF(CU105>15, CU105, 0) -> 0 | CX105: 8.89 | CY105: 0 | CZ105: =IF((CY105>10)*(CY105<=12),CY105,0) -> 0 | DA105: =IF((CY105>12)*(CY105<=14),CY105,0) -> 0 | DB105: =IF(CY105<10, 0, CY105) -> 0 | DC105: 0 | DD105: 0 | DE105: 0 | DF105: 0 | DG105: 852699.1 | DH105: 5126305.4 | DI105: 1034743 | DJ105: 3795367 | DK105: 1633974.1 | DL105: 1774532 | DM105: 4.4013375 | DN105: 24.669656 | DO105: 4.555725 | DP105: 17.013536 | DQ105: 7.81218 | DR105: 10.821067 | DS105: 24.669656 | DT105: 17.013536 | DU105: 7.81218 | DV105: 10.821067 | DW105: 4.4013375 | DX105: 4.555725 | DY105: 27.3 | DZ105: 14.74 | EA105: 26.47 | EB105: 18.44 | EC105: -3.17 | ED105: 0 | EE105: 24.42 | EF105: 8.64 | EG105: 15.28 | EH105: 18.65 | EI105: 21.09 | EJ105: 0 | EK105: =AVERAGE(DZ105, EF105) -> 11.69 | EL105: 193736.36 | EM105: 207798.01 | EN105: 227130.25 | EO105: 223079.26 | EP105: 209157.26 | EQ105: 163988.63 | ER105: 1.1723677 | ES105: 1.073539 | ET105: 1.0065412 | EU105: 0.78917326 | EV105: 0.85297471 | EW105: 0.93149856 | EX105: 0.93759168 | EY105: 0.73511375 | EZ105: 0.99350131 | FA105: 1.0665624 | FB105: 0.78404467 | FC105: 1.2671489 | FD105: 1.3603337 | FE105: 1.2754375 | FF105: 0 | FG105: 0 | FH105: 0 | FI105: 0 | FJ105: 0 | FK105: 0 | FL105: 0 | FM105: 0 | FN105: 0 | FO105: 0 | FP105: 0 | FQ105: 0 | FR105: 0 | FS105: 0 | FT105: 0 | FU105: 0 | FV105: 0 | FW105: 0 | FX105: 0 | FY105: 0 | FZ105: 0 | GA105: 0 | GB105: 0 | GC105: 0 | GD105: 0 | GE105: 0 | GF105: 0 | GG105: 0 | GH105: 0 | GI105: 0 | GJ105: 0 | GK105: 0 | GL105: 0 | GM105: 14.74 | GN105: 0 | GO105: 0 | GP105: 0 | GQ105: 0 | GR105: 0 | GS105: 0

Sheet B_hlookup and sumif
A1: Back to Instructions
D3: constant | E3: - | F3: - | G3: - | H3: - | I3: - | J3: - | K3: - | L3: - | M3: - | N3: - | O3: - | P3: + | Q3: + | R3: + | V3: MAPE =
C4: betas | D4: 19.876849 | E4: -11.502467 | F4: -1.0372421 | G4: -1.8968974 | H4: -2.053687 | I4: -2.0304706 | J4: -0.22885998 | K4: -0.12525245 | L4: -0.084895038 | M4: -0.048167526 | N4: -0.088585602 | O4: 0.046744919 | P4: 3.3876558 | Q4: 0.1198744 | R4: 2.4784483 | V4: =AVERAGE(V6:V108) -> 0.10191385
C5: week | D5: actual volume | E5: pi.ML.POLVO_BOLD.POLVO | F5: promo.Ace.Pwd.InOut.Na | G5: promo.Ariel.Pwd.InOut.Na | H5: promo.Bold.Pwd.Incase.1kg | I5: promo.Bold.Pwd.Incase.Manta | J5: percdisc.147030.ACE.POLVO.MB | K5: percdisc.75711.ACE.POLVO.BEBE | L5: percdisc.188231.ARIEL.POLVO.MB_10to12 | M5: percdisc.188231.ARIEL.POLVO.MB_12to14 | N5: flyer.Ariel.Pwd | O5: percpinc.231508.ARIEL.POLVO.BLACK | P5: xmas_dummy | Q5: percdisc.149681.ML.POLVO.MB | R5: flyer.ML.Pwd | S5: base | T5: expected volume | U5: perc error | V5: abs perc error
B6: 2 | C6: 200725 | D6: 6.0803818 | E6: =HLOOKUP(E$5, 'DATA FOR ASSIGNMENT 4b'!$A$2:$ZZ$500, ROW(A1)+1, FALSE) * E$4 -> -9.2889008 | F6: =HLOOKUP(F$5, 'DATA FOR ASSIGNMENT 4b'!$A$2:$ZZ$500, ROW(B1)+1, FALSE) * F$4 -> -1.0372421 | G6: =HLOOKUP(G$5, 'DATA FOR ASSIGNMENT 4b'!$A$2:$ZZ$500, ROW(C1)+1, FALSE) * G$4 -> -1.8968974 | H6: =HLOOKUP(H$5, 'DATA FOR ASSIGNMENT 4b'!$A$2:$ZZ$500, ROW(D1)+1, FALSE) * H$4 -> -2.053687 | I6: =HLOOKUP(I$5, 'DATA FOR ASSIGNMENT 4b'!$A$2:$ZZ$500, ROW(E1)+1, FALSE) * I$4 -> 0 | J6: =HLOOKUP(J$5, 'DATA FOR ASSIGNMENT 4b'!$A$2:$ZZ$500, ROW(F1)+1, FALSE) * J$4 -> 0 | K6: =HLOOKUP(K$5, 'DATA FOR ASSIGNMENT 4b'!$A$2:$ZZ$500, ROW(G1)+1, FALSE) * K$4 -> 0 | L6: =HLOOKUP(L$5, 'DATA FOR ASSIGNMENT 4b'!$A$2:$ZZ$500, ROW(H1)+1, FALSE) * L$4 -> 0 | ... R6: =HLOOKUP(R$5, 'DATA FOR ASSIGNMENT 4b'!$A$2:$ZZ$500, ROW(N1)+1, FALSE) * R$4 -> 0 | S6: =SUMIF(E6:R6, "<0") + $D$4 -> 5.6001222 | T6: =SUM($D$4, E6:R6) -> 5.6001222 | U6: =(D6-T6)/D6 -> 0.07898511 | V6: =ABS(U6) -> 0.07898511
B7: =+B6+1 -> 3 | C7: 200726 | D7: 7.0952162 | E7: =HLOOKUP(E$5, 'DATA FOR ASSIGNMENT 4b'!$A$2:$ZZ$500, ROW(A2)+1, FALSE) * E$4 -> -9.3748734 | F7: =HLOOKUP(F$5, 'DATA FOR ASSIGNMENT 4b'!$A$2:$ZZ$500, ROW(B2)+1, FALSE) * F$4 -> -1.0372421 | G7: =HLOOKUP(G$5, 'DATA FOR ASSIGNMENT 4b'!$A$2:$ZZ$500, ROW(C2)+1, FALSE) * G$4 -> -1.8968974 | H7: =HLOOKUP(H$5, 'DATA FOR ASSIGNMENT 4b'!$A$2:$ZZ$500, ROW(D2)+1, FALSE) * H$4 -> -2.053687 | I7: =HLOOKUP(I$5, 'DATA FOR ASSIGNMENT 4b'!$A$2:$ZZ$500, ROW(E2)+1, FALSE) * I$4 -> 0 | J7: =HLOOKUP(J$5, 'DATA FOR ASSIGNMENT 4b'!$A$2:$ZZ$500, ROW(F2)+1, FALSE) * J$4 -> 0 | K7: =HLOOKUP(K$5, 'DATA FOR ASSIGNMENT 4b'!$A$2:$ZZ$500, ROW(G2)+1, FALSE) * K$4 -> 0 | L7: =HLOOKUP(L$5, 'DATA FOR ASSIGNMENT 4b'!$A$2:$ZZ$500, ROW(H2)+1, FALSE) * L$4 -> 0 | ... R7: =HLOOKUP(R$5, 'DATA FOR ASSIGNMENT 4b'!$A$2:$ZZ$500, ROW(N2)+1, FALSE) * R$4 -> 0 | S7: =SUMIF(E7:R7, "<0") + $D$4 -> 5.5141496 | T7: =SUM($D$4, E7:R7) -> 5.5141496 | U7: =(D7-T7)/D7 -> 0.22283558 | V7: =ABS(U7) -> 0.22283558
B8: =+B7+1 -> 4 | C8: 200727 | D8: 7.0885081 | E8: =HLOOKUP(E$5, 'DATA FOR ASSIGNMENT 4b'!$A$2:$ZZ$500, ROW(A3)+1, FALSE) * E$4 -> -9.199112 | F8: =HLOOKUP(F$5, 'DATA FOR ASSIGNMENT 4b'!$A$2:$ZZ$500, ROW(B3)+1, FALSE) * F$4 -> -1.0372421 | G8: =HLOOKUP(G$5, 'DATA FOR ASSIGNMENT 4b'!$A$2:$ZZ$500, ROW(C3)+1, FALSE) * G$4 -> -1.8968974 | H8: =HLOOKUP(H$5, 'DATA FOR ASSIGNMENT 4b'!$A$2:$ZZ$500, ROW(D3)+1, FALSE) * H$4 -> -2.053687 | I8: =HLOOKUP(I$5, 'DATA FOR ASSIGNMENT 4b'!$A$2:$ZZ$500, ROW(E3)+1, FALSE) * I$4 -> 0 | J8: =HLOOKUP(J$5, 'DATA FOR ASSIGNMENT 4b'!$A$2:$ZZ$500, ROW(F3)+1, FALSE) * J$4 -> 0 | K8: =HLOOKUP(K$5, 'DATA FOR ASSIGNMENT 4b'!$A$2:$ZZ$500, ROW(G3)+1, FALSE) * K$4 -> 0 | L8: =HLOOKUP(L$5, 'DATA FOR ASSIGNMENT 4b'!$A$2:$ZZ$500, ROW(H3)+1, FALSE) * L$4 -> 0 | ... R8: =HLOOKUP(R$5, 'DATA FOR ASSIGNMENT 4b'!$A$2:$ZZ$500, ROW(N3)+1, FALSE) * R$4 -> 0 | S8: =SUMIF(E8:R8, "<0") + $D$4 -> 5.689911 | T8: =SUM($D$4, E8:R8) -> 5.689911 | U8: =(D8-T8)/D8 -> 0.19730486 | V8: =ABS(U8) -> 0.19730486
B9: =+B8+1 -> 5 | C9: 200728 | D9: 7.0405934 | E9: =HLOOKUP(E$5, 'DATA FOR ASSIGNMENT 4b'!$A$2:$ZZ$500, ROW(A4)+1, FALSE) * E$4 -> -9.4107684 | F9: =HLOOKUP(F$5, 'DATA FOR ASSIGNMENT 4b'!$A$2:$ZZ$500, ROW(B4)+1, FALSE) * F$4 -> -1.0372421 | G9: =HLOOKUP(G$5, 'DATA FOR ASSIGNMENT 4b'!$A$2:$ZZ$500, ROW(C4)+1, FALSE) * G$4 -> 0 | H9: =HLOOKUP(H$5, 'DATA FOR ASSIGNMENT 4b'!$A$2:$ZZ$500, ROW(D4)+1, FALSE) * H$4 -> -2.053687 | I9: =HLOOKUP(I$5, 'DATA FOR ASSIGNMENT 4b'!$A$2:$ZZ$500, ROW(E4)+1, FALSE) * I$4 -> 0 | J9: =HLOOKUP(J$5, 'DATA FOR ASSIGNMENT 4b'!$A$2:$ZZ$500, ROW(F4)+1, FALSE) * J$4 -> 0 | K9: =HLOOKUP(K$5, 'DATA FOR ASSIGNMENT 4b'!$A$2:$ZZ$500, ROW(G4)+1, FALSE) * K$4 -> 0 | L9: =HLOOKUP(L$5, 'DATA FOR ASSIGNMENT 4b'!$A$2:$ZZ$500, ROW(H4)+1, FALSE) * L$4 -> 0 | ... R9: =HLOOKUP(R$5, 'DATA FOR ASSIGNMENT 4b'!$A$2:$ZZ$500, ROW(N4)+1, FALSE) * R$4 -> 0 | S9: =SUMIF(E9:R9, "<0") + $D$4 -> 7.375152 | T9: =SUM($D$4, E9:R9) -> 7.375152 | U9: =(D9-T9)/D9 -> -0.047518528 | V9: =ABS(U9) -> 0.047518528
B10: =+B9+1 -> 6 | C10: 200729 | D10: 5.9347209 | E10: =HLOOKUP(E$5, 'DATA FOR ASSIGNMENT 4b'!$A$2:$ZZ$500, ROW(A5)+1, FALSE) * E$4 -> -9.3914717 | F10: =HLOOKUP(F$5, 'DATA FOR ASSIGNMENT 4b'!$A$2:$ZZ$500, ROW(B5)+1, FALSE) * F$4 -> -1.0372421 | G10: =HLOOKUP(G$5, 'DATA FOR ASSIGNMENT 4b'!$A$2:$ZZ$500, ROW(C5)+1, FALSE) * G$4 -> 0 | H10: =HLOOKUP(H$5, 'DATA FOR ASSIGNMENT 4b'!$A$2:$ZZ$500, ROW(D5)+1, FALSE) * H$4 -> -2.053687 | I10: =HLOOKUP(I$5, 'DATA FOR ASSIGNMENT 4b'!$A$2:$ZZ$500, ROW(E5)+1, FALSE) * I$4 -> 0 | J10: =HLOOKUP(J$5, 'DATA FOR ASSIGNMENT 4b'!$A$2:$ZZ$500, ROW(F5)+1, FALSE) * J$4 -> 0 | K10: =HLOOKUP(K$5, 'DATA FOR ASSIGNMENT 4b'!$A$2:$ZZ$500, ROW(G5)+1, FALSE) * K$4 -> 0 | L10: =HLOOKUP(L$5, 'DATA FOR ASSIGNMENT 4b'!$A$2:$ZZ$500, ROW(H5)+1, FALSE) * L$4 -> 0 | ... R10: =HLOOKUP(R$5, 'DATA FOR ASSIGNMENT 4b'!$A$2:$ZZ$500, ROW(N5)+1, FALSE) * R$4 -> 0 | S10: =SUMIF(E10:R10, "<0") + $D$4 -> 7.3944487 | T10: =SUM($D$4, E10:R10) -> 7.3944487 | U10: =(D10-T10)/D10 -> -0.24596401 | V10: =ABS(U10) -> 0.24596401
B11: =+B10+1 -> 7 | C11: 200730 | D11: 5.9356792 | E11: =HLOOKUP(E$5, 'DATA FOR ASSIGNMENT 4b'!$A$2:$ZZ$500, ROW(A6)+1, FALSE) * E$4 -> -9.3562888 | F11: =HLOOKUP(F$5, 'DATA FOR ASSIGNMENT 4b'!$A$2:$ZZ$500, ROW(B6)+1, FALSE) * F$4 -> -1.0372421 | G11: =HLOOKUP(G$5, 'DATA FOR ASSIGNMENT 4b'!$A$2:$ZZ$500, ROW(C6)+1, FALSE) * G$4 -> 0 | H11: =HLOOKUP(H$5, 'DATA FOR ASSIGNMENT 4b'!$A$2:$ZZ$500, ROW(D6)+1, FALSE) * H$4 -> -2.053687 | I11: =HLOOKUP(I$5, 'DATA FOR ASSIGNMENT 4b'!$A$2:$ZZ$500, ROW(E6)+1, FALSE) * I$4 -> 0 | J11: =HLOOKUP(J$5, 'DATA FOR ASSIGNMENT 4b'!$A$2:$ZZ$500, ROW(F6)+1, FALSE) * J$4 -> 0 | K11: =HLOOKUP(K$5, 'DATA FOR ASSIGNMENT 4b'!$A$2:$ZZ$500, ROW(G6)+1, FALSE) * K$4 -> 0 | L11: =HLOOKUP(L$5, 'DATA FOR ASSIGNMENT 4b'!$A$2:$ZZ$500, ROW(H6)+1, FALSE) * L$4 -> 0 | ... R11: =HLOOKUP(R$5, 'DATA FOR ASSIGNMENT 4b'!$A$2:$ZZ$500, ROW(N6)+1, FALSE) * R$4 -> 0 | S11: =SUMIF(E11:R11, "<0") + $D$4 -> 7.4296316 | T11: =SUM($D$4, E11:R11) -> 7.4296316 | U11: =(D11-T11)/D11 -> -0.25169021 | V11: =ABS(U11) -> 0.25169021
B12: =+B11+1 -> 8 | C12: 200731 | D12: 7.2782505 | E12: =HLOOKUP(E$5, 'DATA FOR ASSIGNMENT 4b'!$A$2:$ZZ$500, ROW(A7)+1, FALSE) * E$4 -> -9.3359853 | F12: =HLOOKUP(F$5, 'DATA FOR ASSIGNMENT 4b'!$A$2:$ZZ$500, ROW(B7)+1, FALSE) * F$4 -> -1.0372421 | G12: =HLOOKUP(G$5, 'DATA FOR ASSIGNMENT 4b'!$A$2:$ZZ$500, ROW(C7)+1, FALSE) * G$4 -> 0 | H12: =HLOOKUP(H$5, 'DATA FOR ASSIGNMENT 4b'!$A$2:$ZZ$500, ROW(D7)+1, FALSE) * H$4 -> -2.053687 | I12: =HLOOKUP(I$5, 'DATA FOR ASSIGNMENT 4b'!$A$2:$ZZ$500, ROW(E7)+1, FALSE) * I$4 -> 0 | J12: =HLOOKUP(J$5, 'DATA FOR ASSIGNMENT 4b'!$A$2:$ZZ$500, ROW(F7)+1, FALSE) * J$4 -> 0 | K12: =HLOOKUP(K$5, 'DATA FOR ASSIGNMENT 4b'!$A$2:$ZZ$500, ROW(G7)+1, FALSE) * K$4 -> 0 | L12: =HLOOKUP(L$5, 'DATA FOR ASSIGNMENT 4b'!$A$2:$ZZ$500, ROW(H7)+1, FALSE) * L$4 -> 0 | ... R12: =HLOOKUP(R$5, 'DATA FOR ASSIGNMENT 4b'!$A$2:$ZZ$500, ROW(N7)+1, FALSE) * R$4 -> 0 | S12: =SUMIF(E12:R12, "<0") + $D$4 -> 7.4499351 | T12: =SUM($D$4, E12:R12) -> 7.4499351 | U12: =(D12-T12)/D12 -> -0.02358871 | V12: =ABS(U12) -> 0.02358871
B13: =+B12+1 -> 9 | C13: 200732 | D13: 6.3113309 | E13: =HLOOKUP(E$5, 'DATA FOR ASSIGNMENT 4b'!$A$2:$ZZ$500, ROW(A8)+1, FALSE) * E$4 -> -9.3825919 | F13: =HLOOKUP(F$5, 'DATA FOR ASSIGNMENT 4b'!$A$2:$ZZ$500, ROW(B8)+1, FALSE) * F$4 -> 0 | G13: =HLOOKUP(G$5, 'DATA FOR ASSIGNMENT 4b'!$A$2:$ZZ$500, ROW(C8)+1, FALSE) * G$4 -> -1.8968974 | H13: =HLOOKUP(H$5, 'DATA FOR ASSIGNMENT 4b'!$A$2:$ZZ$500, ROW(D8)+1, FALSE) * H$4 -> 0 | I13: =HLOOKUP(I$5, 'DATA FOR ASSIGNMENT 4b'!$A$2:$ZZ$500, ROW(E8)+1, FALSE) * I$4 -> 0 | J13: =HLOOKUP(J$5, 'DATA FOR ASSIGNMENT 4b'!$A$2:$ZZ$500, ROW(F8)+1, FALSE) * J$4 -> 0 | K13: =HLOOKUP(K$5, 'DATA FOR ASSIGNMENT 4b'!$A$2:$ZZ$500, ROW(G8)+1, FALSE) * K$4 -> -1.8812918 | L13: =HLOOKUP(L$5, 'DATA FOR ASSIGNMENT 4b'!$A$2:$ZZ$500, ROW(H8)+1, FALSE) * L$4 -> 0 | ... R13: =HLOOKUP(R$5, 'DATA FOR ASSIGNMENT 4b'!$A$2:$ZZ$500, ROW(N8)+1, FALSE) * R$4 -> 0 | S13: =SUMIF(E13:R13, "<0") + $D$4 -> 6.7160683 | T13: =SUM($D$4, E13:R13) -> 6.7160683 | U13: =(D13-T13)/D13 -> -0.064128699 | V13: =ABS(U13) -> 0.064128699
B14: =+B13+1 -> 10 | C14: 200733 | D14: 6.7454385 | E14: =HLOOKUP(E$5, 'DATA FOR ASSIGNMENT 4b'!$A$2:$ZZ$500, ROW(A9)+1, FALSE) * E$4 -> -9.5007141 | F14: =HLOOKUP(F$5, 'DATA FOR ASSIGNMENT 4b'!$A$2:$ZZ$500, ROW(B9)+1, FALSE) * F$4 -> 0 | G14: =HLOOKUP(G$5, 'DATA FOR ASSIGNMENT 4b'!$A$2:$ZZ$500, ROW(C9)+1, FALSE) * G$4 -> -1.8968974 | H14: =HLOOKUP(H$5, 'DATA FOR ASSIGNMENT 4b'!$A$2:$ZZ$500, ROW(D9)+1, FALSE) * H$4 -> 0 | I14: =HLOOKUP(I$5, 'DATA FOR ASSIGNMENT 4b'!$A$2:$ZZ$500, ROW(E9)+1, FALSE) * I$4 -> 0 | J14: =HLOOKUP(J$5, 'DATA FOR ASSIGNMENT 4b'!$A$2:$ZZ$500, ROW(F9)+1, FALSE) * J$4 -> 0 | K14: =HLOOKUP(K$5, 'DATA FOR ASSIGNMENT 4b'!$A$2:$ZZ$500, ROW(G9)+1, FALSE) * K$4 -> -1.6157566 | L14: =HLOOKUP(L$5, 'DATA FOR ASSIGNMENT 4b'!$A$2:$ZZ$500, ROW(H9)+1, FALSE) * L$4 -> 0 | ... R14: =HLOOKUP(R$5, 'DATA FOR ASSIGNMENT 4b'!$A$2:$ZZ$500, ROW(N9)+1, FALSE) * R$4 -> 0 | S14: =SUMIF(E14:R14, "<0") + $D$4 -> 6.8634813 | T14: =SUM($D$4, E14:R14) -> 6.8634813 | U14: =(D14-T14)/D14 -> -0.017499655 | V14: =ABS(U14) -> 0.017499655
B15: =+B14+1 -> 11 | C15: 200734 | D15: 6.9850123 | E15: =HLOOKUP(E$5, 'DATA FOR ASSIGNMENT 4b'!$A$2:$ZZ$500, ROW(A10)+1, FALSE) * E$4 -> -9.4652709 | F15: =HLOOKUP(F$5, 'DATA FOR ASSIGNMENT 4b'!$A$2:$ZZ$500, ROW(B10)+1, FALSE) * F$4 -> 0 | G15: =HLOOKUP(G$5, 'DATA FOR ASSIGNMENT 4b'!$A$2:$ZZ$500, ROW(C10)+1, FALSE) * G$4 -> -1.8968974 | H15: =HLOOKUP(H$5, 'DATA FOR ASSIGNMENT 4b'!$A$2:$ZZ$500, ROW(D10)+1, FALSE) * H$4 -> 0 | I15: =HLOOKUP(I$5, 'DATA FOR ASSIGNMENT 4b'!$A$2:$ZZ$500, ROW(E10)+1, FALSE) * I$4 -> 0 | J15: =HLOOKUP(J$5, 'DATA FOR ASSIGNMENT 4b'!$A$2:$ZZ$500, ROW(F10)+1, FALSE) * J$4 -> 0 | K15: =HLOOKUP(K$5, 'DATA FOR ASSIGNMENT 4b'!$A$2:$ZZ$500, ROW(G10)+1, FALSE) * K$4 -> 0 | L15: =HLOOKUP(L$5, 'DATA FOR ASSIGNMENT 4b'!$A$2:$ZZ$500, ROW(H10)+1, FALSE) * L$4 -> 0 | ... R15: =HLOOKUP(R$5, 'DATA FOR ASSIGNMENT 4b'!$A$2:$ZZ$500, ROW(N10)+1, FALSE) * R$4 -> 0 | S15: =SUMIF(E15:R15, "<0") + $D$4 -> 8.5146811 | T15: =SUM($D$4, E15:R15) -> 8.5146811 | U15: =(D15-T15)/D15 -> -0.21899301 | V15: =ABS(U15) -> 0.21899301
B16: =+B15+1 -> 12 | C16: 200735 | D16: 8.1378411 | E16: =HLOOKUP(E$5, 'DATA FOR ASSIGNMENT 4b'!$A$2:$ZZ$500, ROW(A11)+1, FALSE) * E$4 -> -9.4195457 | F16: =HLOOKUP(F$5, 'DATA FOR ASSIGNMENT 4b'!$A$2:$ZZ$500, ROW(B11)+1, FALSE) * F$4 -> 0 | G16: =HLOOKUP(G$5, 'DATA FOR ASSIGNMENT 4b'!$A$2:$ZZ$500, ROW(C11)+1, FALSE) * G$4 -> -1.8968974 | H16: =HLOOKUP(H$5, 'DATA FOR ASSIGNMENT 4b'!$A$2:$ZZ$500, ROW(D11)+1, FALSE) * H$4 -> 0 | I16: =HLOOKUP(I$5, 'DATA FOR ASSIGNMENT 4b'!$A$2:$ZZ$500, ROW(E11)+1, FALSE) * I$4 -> 0 | J16: =HLOOKUP(J$5, 'DATA FOR ASSIGNMENT 4b'!$A$2:$ZZ$500, ROW(F11)+1, FALSE) * J$4 -> 0 | K16: =HLOOKUP(K$5, 'DATA FOR ASSIGNMENT 4b'!$A$2:$ZZ$500, ROW(G11)+1, FALSE) * K$4 -> 0 | L16: =HLOOKUP(L$5, 'DATA FOR ASSIGNMENT 4b'!$A$2:$ZZ$500, ROW(H11)+1, FALSE) * L$4 -> 0 | ... R16: =HLOOKUP(R$5, 'DATA FOR ASSIGNMENT 4b'!$A$2:$ZZ$500, ROW(N11)+1, FALSE) * R$4 -> 0 | S16: =SUMIF(E16:R16, "<0") + $D$4 -> 8.5604064 | T16: =SUM($D$4, E16:R16) -> 8.5604064 | U16: =(D16-T16)/D16 -> -0.05192596 | V16: =ABS(U16) -> 0.05192596
B17: =+B16+1 -> 13 | C17: 200736 | D17: 6.9620132 | E17: =HLOOKUP(E$5, 'DATA FOR ASSIGNMENT 4b'!$A$2:$ZZ$500, ROW(A12)+1, FALSE) * E$4 -> -9.3860038 | F17: =HLOOKUP(F$5, 'DATA FOR ASSIGNMENT 4b'!$A$2:$ZZ$500, ROW(B12)+1, FALSE) * F$4 -> 0 | G17: =HLOOKUP(G$5, 'DATA FOR ASSIGNMENT 4b'!$A$2:$ZZ$500, ROW(C12)+1, FALSE) * G$4 -> -1.8968974 | H17: =HLOOKUP(H$5, 'DATA FOR ASSIGNMENT 4b'!$A$2:$ZZ$500, ROW(D12)+1, FALSE) * H$4 -> 0 | I17: =HLOOKUP(I$5, 'DATA FOR ASSIGNMENT 4b'!$A$2:$ZZ$500, ROW(E12)+1, FALSE) * I$4 -> 0 | J17: =HLOOKUP(J$5, 'DATA FOR ASSIGNMENT 4b'!$A$2:$ZZ$500, ROW(F12)+1, FALSE) * J$4 -> 0 | K17: =HLOOKUP(K$5, 'DATA FOR ASSIGNMENT 4b'!$A$2:$ZZ$500, ROW(G12)+1, FALSE) * K$4 -> -2.0879584 | L17: =HLOOKUP(L$5, 'DATA FOR ASSIGNMENT 4b'!$A$2:$ZZ$500, ROW(H12)+1, FALSE) * L$4 -> 0 | ... R17: =HLOOKUP(R$5, 'DATA FOR ASSIGNMENT 4b'!$A$2:$ZZ$500, ROW(N12)+1, FALSE) * R$4 -> 0 | S17: =SUMIF(E17:R17, "<0") + $D$4 -> 6.5059898 | T17: =SUM($D$4, E17:R17) -> 6.5059898 | U17: =(D17-T17)/D17 -> 0.065501648 | V17: =ABS(U17) -> 0.065501648
B18: =+B17+1 -> 14 | C18: 200737 | D18: 7.7823137 | E18: =HLOOKUP(E$5, 'DATA FOR ASSIGNMENT 4b'!$A$2:$ZZ$500, ROW(A13)+1, FALSE) * E$4 -> -9.3772097 | F18: =HLOOKUP(F$5, 'DATA FOR ASSIGNMENT 4b'!$A$2:$ZZ$500, ROW(B13)+1, FALSE) * F$4 -> 0 | G18: =HLOOKUP(G$5, 'DATA FOR ASSIGNMENT 4b'!$A$2:$ZZ$500, ROW(C13)+1, FALSE) * G$4 -> -1.8968974 | H18: =HLOOKUP(H$5, 'DATA FOR ASSIGNMENT 4b'!$A$2:$ZZ$500, ROW(D13)+1, FALSE) * H$4 -> 0 | I18: =HLOOKUP(I$5, 'DATA FOR ASSIGNMENT 4b'!$A$2:$ZZ$500, ROW(E13)+1, FALSE) * I$4 -> 0 | J18: =HLOOKUP(J$5, 'DATA FOR ASSIGNMENT 4b'!$A$2:$ZZ$500, ROW(F13)+1, FALSE) * J$4 -> 0 | K18: =HLOOKUP(K$5, 'DATA FOR ASSIGNMENT 4b'!$A$2:$ZZ$500, ROW(G13)+1, FALSE) * K$4 -> 0 | L18: =HLOOKUP(L$5, 'DATA FOR ASSIGNMENT 4b'!$A$2:$ZZ$500, ROW(H13)+1, FALSE) * L$4 -> -0.89054895 | ... R18: =HLOOKUP(R$5, 'DATA FOR ASSIGNMENT 4b'!$A$2:$ZZ$500, ROW(N13)+1, FALSE) * R$4 -> 0 | S18: =SUMIF(E18:R18, "<0") + $D$4 -> 7.7121933 | T18: =SUM($D$4, E18:R18) -> 7.7121933 | U18: =(D18-T18)/D18 -> 0.009010219 | V18: =ABS(U18) -> 0.009010219
... B108: =+B107+1 -> 104 | C108: 200923 | D108: 10.821067 | E108: =HLOOKUP(E$5, 'DATA FOR ASSIGNMENT 4b'!$A$2:$ZZ$500, ROW(A103)+1, FALSE) * E$4 -> -9.0184478 | F108: =HLOOKUP(F$5, 'DATA FOR ASSIGNMENT 4b'!$A$2:$ZZ$500, ROW(B103)+1, FALSE) * F$4 -> -1.0372421 | G108: =HLOOKUP(G$5, 'DATA FOR ASSIGNMENT 4b'!$A$2:$ZZ$500, ROW(C103)+1, FALSE) * G$4 -> 0 | H108: =HLOOKUP(H$5, 'DATA FOR ASSIGNMENT 4b'!$A$2:$ZZ$500, ROW(D103)+1, FALSE) * H$4 -> 0 | I108: =HLOOKUP(I$5, 'DATA FOR ASSIGNMENT 4b'!$A$2:$ZZ$500, ROW(E103)+1, FALSE) * I$4 -> 0 | J108: =HLOOKUP(J$5, 'DATA FOR ASSIGNMENT 4b'!$A$2:$ZZ$500, ROW(F103)+1, FALSE) * J$4 -> 0 | K108: =HLOOKUP(K$5, 'DATA FOR ASSIGNMENT 4b'!$A$2:$ZZ$500, ROW(G103)+1, FALSE) * K$4 -> 0 | L108: =HLOOKUP(L$5, 'DATA FOR ASSIGNMENT 4b'!$A$2:$ZZ$500, ROW(H103)+1, FALSE) * L$4 -> 0 | ... R108: =HLOOKUP(R$5, 'DATA FOR ASSIGNMENT 4b'!$A$2:$ZZ$500, ROW(N103)+1, FALSE) * R$4 -> 0 | S108: =SUMIF(E108:R108, "<0") + $D$4 -> 9.8211596 | T108: =SUM($D$4, E108:R108) -> 9.8211596 | U108: =(D108-T108)/D108 -> 0.092403784 | V108: =ABS(U108) -> 0.092403784

Sheet string functions 1 - key table
A2: 0 | B2: Category
